Workbook
Name _ftn1: DIP!$M$14
Name _ftn2: DIP!#REF!
Name _ftn3: DIP!$M$15
Name _Hlk49441128: 'Credit terms'!$C$82
Name _Hlk49441128: 'Lawyers terms'!$C$103
Name _Hlk83203796: DIP!$A$83
Name _Hlk84245425: DIP!$A$57
Name _Hlk98754409: DIP!$K$59
Name _Hlk99544404: 'Credit terms'!$C$23
Name _Hlk99544404: 'Lawyers terms'!$C$28
Name Amber_P: #REF!
Name Amber_P: #REF!
Name APR: #REF!
Name APR: #REF!
Name APR: #REF!
Name APR: 'KB_CRITERIA AND CALCULATION '!$L$32
Name Bank_Rate: 'EBITDA calc_'!#REF!
Name Bank_Rate: #REF!
Name Bank_Rate: #REF!
Name BankBase: #REF!
Name BankBase: #REF!
Name BBR: #REF!
Name BBR: #REF!
Name BBR: #REF!
Name BBR: 'Product Data'!$E$3
Name BBR_Override: 'BTL Calculator WIP'!$K$28
Name BBR_Override: #REF!
Name BBR_Override: #REF!
Name BBR_Override: #REF!
Name BBR_Override: 'BTL Calculator'!$H$31
Name Core_Net_loan: #REF!
Name Core_Net_loan: #REF!
Name Core_Net_loan: #REF!
Name Core_Net_loan: 'KB_CRITERIA AND CALCULATION '!$D$29
Name CoreList: 'Product Data'!#REF!
Name CoreListAdj: 'Product Data'!$Y$22:$Y$24
Name CoreSpecialist: OFFSET('Product Data'!$BR$2, 0, 0, SUMPRODUCT(--(LEN('Product Data'!$BR$2:$BR$100)>0)), 1)
Name CoreTypes: 'Product Data'!$BU$2
Name CoreTypes_All: 'Product Data'!$BU$2:$BU$3
Name CoreTypes2: 'Product Data'!$BU$3
Name Custom_Defer: 'BTL Calculator WIP'!$I$59
Name Custom_Defer: 'BTL Calculator'!$I$67
Name Custom_Rolled: 'BTL Calculator WIP'!$AR$2
Name Custom_Rolled: 'BTL Calculator'!$AS$3
Name Custom_Rolled_Actual: 'KB_CRITERIA AND CALCULATION '!$K$88
Name DD_In_Month1: 'DD (2)'!$T$15
Name DD_In_Month1: #REF!
Name DD_In_Month1: #REF!
Name DD_In_Month1: #REF!
Name DD_In_Month1: DD!$T$15
Name Defer_int: 'BTL Calculator WIP'!$I$59
Name Defer_int: 'BTL Calculator'!$I$67
Name Defer_Term_Override: 'BTL Calculator WIP'!$AN$26
Name Defer_Term_Override: #REF!
Name Defer_Term_Override: #REF!
Name Defer_Term_Override: #REF!
Name Defer_Term_Override: 'BTL Calculator'!$CY$8
Name Defer2: #REF!
Name Defer2: #REF!
Name Defer2: #REF!

Sheet BTL Calculator WIP
J1: UNDERWRITER BTL Calculator | W1: Version 03.08.23 | AO1: BDM? | AP1: Messages | AQ1: Term Radio Button | AR1: RADIO ROLLED | AT1: Radio Rolled vs Deferred
B2: User Inputs | AO2: Hide: Section 3 and row 150 onwards. Only include calc and holiday let tabs | AQ2: 1 | AR2: 4
B4: The Borrower | I4: Hubspot Loan Ref: | K4: 0000000000 | R4: Property Details | AA4: Property Value | AB4: 450000 | AO4: Message formula check with underwriters, compared to the product fee, less the proc fee not just product fee
I5: Borrower Name: | K5: Borrower Name | AA5: Rent Charged | AB5: Monthly
AA6: ="Estimated "&AB5&" Gross Rent" -> Estimated Monthly Gross Rent | AB6: 2200 | AD6: Obtained from broker enquiry or AST if already rented
I7: Property Address: | K7: Property Address | AB7: =Monthly_Rent -> 0
AA8: Property Postcode | AB8: SE18 | AD8: ="HPI Adjusted in 2022 "&TEXT(HPIAdjusted2022/1000000,"£ #0.##0")&"m, 2023 "&TEXT(HPIAdjusted2023/1000000,"£ #0.##0")&"m, 2024 "&TEXT(HPIAdjusted2024/1000000,"£ #0.##0")&"m, 2025 "&TEXT(HPIAdjusted2025/1000000,"£ #0.##0")&"m" -> #N/A
AA9: Property Region | AB9: London | AD9: =IFERROR("Recommended from postcode - "&'KB_CRITERIA AND CALCULATION '!F21,"")
I10: First time Landlord? | K10: No | AA10: Borrower in a restricted country? | AB10: No | AD10: Restricted countries: **Afghanistan, Bosnia Herzegovina, Burundi, Central African Republic, Cuba, Democratic People's Republic of Korea, Democratic Republic of the Congo, Eritrea, Ethiopia, Iran (Islamic Republic of), Iraq, Laos People's Democratic Republic, Libyan Arab Jamahiriya, Myanmar, Pakistan, Somalia, South Sudan, Sudan, Syrian Arab Republic, Uganda, Vanuatu, Venezuela, Yemen.
I11: Expat/ Foreign National? | K11: No | AA11: HMO? | AB11: No
I12: Have a UK Footprint? | K12: Yes | AA12: MUFB? | AB12: No
I13: Offshore Company/Trust? | K13: No | AA13: Flat above restricted* commercial? | AB13: No | AH13: ='KB_CRITERIA AND CALCULATION '!$L$2 -> Available Funding lines are: Zircon or Pearl
I14: Qualifying adverse credit? | K14: No | AA14: Holiday/ Short term Let? | AB14: No | AH14: =TRIM('KB_CRITERIA AND CALCULATION '!$L$3) -> #N/A | AO14: 1
I15: Missed Mortgage Payments (incl. 2nds) | K15: 0 missed last 24m | AA15: Development Exit? | AB15: No | AO15: 2
I16: Unsecured Card/Loan Payments: (ignore balance<£500) | K16: 0 missed last 24m | O16: (ignore where balance<= £500) | AA16: New Build? | AB16: No | AI16: Pick an investor: | AO16: 3
I17: Qualifying CCJs & Defaults: | K17: 0 in last 24m | O17: (ignore<=£350,telecom, utility) | AI17: ZBL | AO17: 4
I18: Bankruptcy/IVA/DRO: | K18: Never | T18: Summary Loan Outputs | AJ18: DO we need rule to say which lines can do 4/6% product?
T19: Basic | W19: Fully R+D (Broker) | Z19: Fully R+D (Underwriter) | AB19: Custom
B21: Loan Details | I21: Initial Term: | K21: =IF(AQ2=2,36,24) -> 24 | R21: Gross Loan | S21: Tier 1 | T21: =IFERROR(IF(RoundDown,'KB_CRITERIA AND CALCULATION '!R76,'KB_CRITERIA AND CALCULATION '!Q76),"-") -> 0 | W21: =IFERROR(IF(RoundDown,'KB_CRITERIA AND CALCULATION '!R79,'KB_CRITERIA AND CALCULATION '!Q79),"-") -> 0 | Z21: =IFERROR(IF(RoundDown,'KB_CRITERIA AND CALCULATION '!R82,'KB_CRITERIA AND CALCULATION '!Q82),"-") -> 0 | AB21: =IFERROR(IF(RoundDown,'KB_CRITERIA AND CALCULATION '!R85,'KB_CRITERIA AND CALCULATION '!Q85),"-") -> 0 | AD21: =IF(Tier1_Eligible,"","Ineligible for Tier 1") | AO21: ="ERC - "&'Product Data'!AO9&'Product Data'!AO10&'Product Data'!AO11&'Product Data'!AO12&" Final month is ERC free" -> #N/A
I22: Customer Type: | K22: New Customer | S22: Tier 2 | T22: =IF(RoundDown,'KB_CRITERIA AND CALCULATION '!R77,'KB_CRITERIA AND CALCULATION '!Q77) -> 0 | W22: =IF(RoundDown,'KB_CRITERIA AND CALCULATION '!R80,'KB_CRITERIA AND CALCULATION '!Q80) -> 0 | Z22: =IF(RoundDown,'KB_CRITERIA AND CALCULATION '!R83,'KB_CRITERIA AND CALCULATION '!Q83) -> 0 | AB22: =IF(RoundDown,'KB_CRITERIA AND CALCULATION '!R86,'KB_CRITERIA AND CALCULATION '!Q86) -> 0 | AD22: =IF(Tier2_Eligible,"","Ineligible for Tier 2")
I23: Rates: | K23: Tracker | S23: Tier 3 | T23: =IF(RoundDown,'KB_CRITERIA AND CALCULATION '!R78,'KB_CRITERIA AND CALCULATION '!Q78) | W23: =IF(RoundDown,'KB_CRITERIA AND CALCULATION '!R81,'KB_CRITERIA AND CALCULATION '!Q81) | Z23: =IF(RoundDown,'KB_CRITERIA AND CALCULATION '!R84,'KB_CRITERIA AND CALCULATION '!Q84) | AB23: =IF(RoundDown,'KB_CRITERIA AND CALCULATION '!R87,'KB_CRITERIA AND CALCULATION '!Q87) | AD23: =IF(Tier3_Eligible,"","Ineligible for Tier 3") | AE23: Pull down - show all or only tier selected?
I24: Estimated Cheapest Tier: | K24: ='KB_CRITERIA AND CALCULATION '!D36 -> 1) Standard BTL | O24: Select 2/4/6 | S24: Tier 4 | T24: =IF(RoundDown,'KB_CRITERIA AND CALCULATION '!#REF!,'KB_CRITERIA AND CALCULATION '!#REF!) -> #REF! | W24: =IF(RoundDown,'KB_CRITERIA AND CALCULATION '!#REF!,'KB_CRITERIA AND CALCULATION '!#REF!) -> #REF! | Z24: =IF(RoundDown,'KB_CRITERIA AND CALCULATION '!#REF!,'KB_CRITERIA AND CALCULATION '!#REF!) -> #REF! | AB24: =IF(RoundDown,'KB_CRITERIA AND CALCULATION '!#REF!,'KB_CRITERIA AND CALCULATION '!#REF!) -> #REF! | AD24: =IF(Tier4_Eligible,"","Ineligible for Tier 4") | AL24: Additional Calculation Settings:
F25: Tier Rate: | K25: =INDEX('Product Data'!$C$9:$C$16,MATCH($K$24,'Product Data'!$B$9:$B$16,0)) -> 0.0764 | O25: Return correct 2/4/6 rate
I26: Revert Rate: | K26: =INDEX('Product Data'!I:I,MATCH('BTL Calculator WIP'!K24,'Product Data'!B:B,0))+'Product Data'!$E$3 -> 0.1329 | O26: BBR + Margin or MVR | AK26: ="(Tracker Override) Deferred at full term? ("&Term&" months)" -> (Tracker Override) Deferred at full term? (24 months) | AN26: Default (Yes)
I27: Override Rate? | X27: Do we replace with a full grid of products - 2/4/6 for the tier selected? | AK27: (Tracker Override) Set rolled months to: | AN27: Default (Pay Rate)
I28: BBR Override? | X28: Could not do 4 tiers, for three options. Display max loan, max roll defer etc | AK28: Borrower prefers interest to be: | AN28: Rolled | AO28: ="Note: To use setting 'I want a specific amount (Net)', set the preference to be "&'KB_CRITERIA AND CALCULATION '!#REF! -> #REF! | AP28: =IF('KB_CRITERIA AND CALCULATION '!$F$36<=$AO15,TRUE,FALSE) -> TRUE | AR28: =INDEX(AQ32:AQ35,MATCH($AS$32,AP32:AP35,0)) -> TRUE
I29: Product Fee: | K29: =INDEX('Product Data'!F:F,MATCH('BTL Calculator WIP'!K24,'Product Data'!B:B,0)) -> Withdrawn | O29: Return correct 2/4/6 fee | X29: Could also display gross, net in one grid | AK29: Spread Rolled Months to reduce DD? | AN29: No | AO29: Start reduced DD amount in month 1 (not after rolled period) | AP29: =IF('KB_CRITERIA AND CALCULATION '!$F$36<=$AO16,TRUE,FALSE) -> TRUE
AK30: Round Gross Loan to Nearest £'000?
I31: Product Fee Override? | T31: Basic | W31: Fully R+D (Broker) | Z31: Fully R+D (Underwriter) | AB31: Custom | AS31: Selected Tier eligible?
I32: Max Gross LTV for tier: | K32: ='KB_CRITERIA AND CALCULATION '!S36 -> 0.75 | AE32: Table? | AK32: Stress BBR Override? | AP32: ='Product Data'!B9 -> 1) Standard BTL | AQ32: =IF('KB_CRITERIA AND CALCULATION '!$F$36<=$AO14,TRUE,FALSE) -> TRUE | AS32: =Product_Selected -> 1) Standard BTL
I33: Submission route | K33: Broker Direct | R33: Net Loan | S33: Tier 1 | T33: =IFERROR('KB_CRITERIA AND CALCULATION '!AL76,"-") -> 0 | W33: =IFERROR('KB_CRITERIA AND CALCULATION '!AL79,"-") -> 0 | Z33: =IFERROR('KB_CRITERIA AND CALCULATION '!AL82,"-") -> 0 | AB33: =IFERROR('KB_CRITERIA AND CALCULATION '!AL85,"-") -> 0 | AE33: Tier / Prod Fee % & £ / basic max G.loan & LTV / fully roll defer & LTV / custom / roll & defer used / basic max N.loan / fully roll defer / custom / monthly DD
I34: ="Gross "&'Product Data'!$AF$4&" Proc Fee:" -> Gross Broker Proc Fee: | K34: =IFERROR(INDEX('Product Data'!$AE$9:$AE$16,MATCH(K33,'Product Data'!$AD$9:$AD$16,0)),1%) -> 0.01 | S34: Tier 2 | T34: ='KB_CRITERIA AND CALCULATION '!AL77 -> 0 | W34: ='KB_CRITERIA AND CALCULATION '!AL80 -> 0 | Z34: ='KB_CRITERIA AND CALCULATION '!AL83 -> 0 | AB34: ='KB_CRITERIA AND CALCULATION '!AL86 -> 0 | AE34: DO we need ICR in revert period?
I35: ="Gross "&'Product Data'!$AF$4&" Proc Fee override:"&" %" -> Gross Broker Proc Fee override: % | K35: 0.01 | S35: Tier 3 | T35: ='KB_CRITERIA AND CALCULATION '!AL78 | W35: ='KB_CRITERIA AND CALCULATION '!AL81 | Z35: ='KB_CRITERIA AND CALCULATION '!AL84 | AB35: ='KB_CRITERIA AND CALCULATION '!AL87 | AP35: ='Product Data'!B12 -> 0 | AQ35: =IF('KB_CRITERIA AND CALCULATION '!$F$36<=$AO17,TRUE,FALSE) -> TRUE
I36: £ | S36: Tier 4 | T36: ='KB_CRITERIA AND CALCULATION '!#REF! -> #REF! | W36: ='KB_CRITERIA AND CALCULATION '!#REF! -> #REF! | Z36: ='KB_CRITERIA AND CALCULATION '!#REF! -> #REF! | AB36: ='KB_CRITERIA AND CALCULATION '!#REF! -> #REF!
I37: ="Optional Broker fee?"&" %" -> Optional Broker fee? % | O37: =IF(K37>0.01,"Warning: High broker fee","") | AO37: =IF(K38+K37*AJ52<0,"Invalid",IF(K38+K37*AJ52>'BTL Calculator WIP'!M150,"Broker Fee Should be less than the "&TEXT('BTL Calculator WIP'!M150,"£0,0")&" product fee","")) -> #N/A
I38: £ | O38: If red please remove so only the % or the £ is populated!
I39: ERC: | K39: ='Product Data'!AO9&'Product Data'!AO10&'Product Data'!AO11&'Product Data'!AO12&" Final month is ERC free" -> #N/A
R40: ="Max Gross Loan is "&TEXT(MaxGrossLoan,"£ 0,0") -> Max Gross Loan is £ 00 | AB40: ="@ "&TEXT(MaxGrossLoan/$AB$4,"0%")&" LTV" -> @ 0% LTV | AD40: ="On Tier "&'KB_CRITERIA AND CALCULATION '!D36 -> On Tier 1) Standard BTL
B41: =IF(OR('Product Data'!AF4="Broker",'Product Data'!AF4="Client"),"","Please note for this case you do not pay the broker directly, you will be paying the "&'Product Data'!$AF$4)
S42: =IFERROR("Max Net Loan is "&TEXT(IF(COUNTIF(K24,"*1*")=1,MAX(T33:AC36),IF(COUNTIF(K24,"*2*")=1,MAX(T34:AC36),IF(COUNTIF(K24,"*3*")=1,MAX(T35:AC36),IF(COUNTIF(K24,"*4*")=1,MAX(T36:AC36),"")))),"£ 0,0"),0) -> 0 | AC42: =IFERROR("@ "&TEXT(IF(COUNTIF(K24,"*1*")=1,MAX(T33:AC36),IF(COUNTIF(K24,"*2*")=1,MAX(T34:AC36),IF(COUNTIF(K24,"*3*")=1,MAX(T35:AC36),IF(COUNTIF(K24,"*4*")=1,MAX(T36:AC36),""))))/$AB$4,"0%")&" LTV",0) -> 0
...

Sheet HomePage (2)
A1: MFS Underwriter Loan Hub - Main Menu

Sheet HomePage
B2: MFS Underwriter Loan Hub - Main Menu
A15: All links
A17: Hidden sheets | D17: Underwriters | G17: Loan Management
A18: Link | B18: Info | D18: Link | E18: Info | G18: Link | I18: Info
A19: HPI | B19: inputs for Forecast property data | D19: ICR Main calculator | E19: Main Loan info/ calculations for max loan & Tier | G19: Deal lead sheet | I19: All info for the loan
A20: Data | B20: Drop downs /inputs for calcs | D20: DIP | E20: Decision in Principle template | G20: Ext Sheets | I20: Outputs for other sheets
A21: Calcs | B21: calculations | D21: Bespoke Tier Calc | E21: which tier is best | G21: DD | I21: Direct Debit Schedule
A22: Loan Data | B22: Loan information where the hubspot info is pulled into. | D22: Holiday Let | E22: Holiday Let calculator | G22: Checklist Before deal complete | I22: Checklist Before deal complete
A23: HubSpot | B23: Hubspot export | G23: Checklist After deal complete | I23: Checklist After deal complete
G24: Completion statement | I24: Completion statement
G25: funding lines | I25: funding lines
G26: Compliance Checklists | I26: Compliance Checklists
G27: Audit Sheet | I27: Audit Sheet

Sheet ROX WORKINGS
B2: Hidden sheets | C2: Conditional Formatting | D2: Data Validation
B3: HPI | C3: N | D3: N | E3: NEW FIGURES TO BE ADDED
B4: Data | C4: N | D4: N | E4: TO LOOK THROUGH
B5: Calcs | C5: N | D5: N | E5: SORTED
B6: Loan Data | C6: N | D6: Y
B7: HubSpot | C7: N | D7: N | E7: TO LOOK THROUGH
B8: Underwriters | E8: TO LOOK THROUGH
B9: HOME PAGE | C9: N | D9: N | E9: TO LOOK THROUGH
B10: ICR Main calculator | C10: Y | D10: Y | E10: TO LOOK THROUGH
B11: DIP | C11: Y | D11: Y | E11: TO LOOK THROUGH
B12: Bespoke Tier Calc | C12: Y | D12: Y | E12: TO LOOK THROUGH
B13: Holiday Let | C13: N | D13: N | E13: TO LOOK THROUGH
B14: Loan Management | C14: N | D14: N | E14: TO LOOK THROUGH
B15: Deal lead sheet | C15: Y | D15: Y | E15: TO LOOK THROUGH
B16: Ext Sheets | C16: N | D16: N | E16: TO LOOK THROUGH
B17: DD | C17: Y | D17: N | E17: TO LOOK THROUGH
B18: Checklist Before deal complete | C18: Y | D18: Y | E18: TO LOOK THROUGH
B19: Checklist After deal complete | C19: Y | D19: Y | E19: TO LOOK THROUGH
B20: Completion statement | C20: Y | D20: Y | E20: TO LOOK THROUGH
... B23: Audit Sheet | C23: N | D23: Y | E23: TO LOOK THROUGH

Sheet HPI
J1: Future Forecasts for Case (Selected Region)
J2: 2021 | K2: 2022 | L2: 2023 | M2: 2024 | N2: 2025 | O2: 5yrs to 2025
A3: Property Value Used: | C3: =Property_Value -> 0 | E3: Front Front Sheet | I3: Predicted rental growth for region: | J3: =VLOOKUP(($C$7),HPI!$A$27:$G$36,2,FALSE) -> #N/A | K3: =VLOOKUP(($C$7),HPI!$A$27:$G$36,3,FALSE) -> #N/A | L3: =VLOOKUP(($C$7),HPI!$A$27:$G$36,4,FALSE) -> #N/A | M3: =VLOOKUP(($C$7),HPI!$A$27:$G$36,5,FALSE) -> #N/A | N3: =VLOOKUP(($C$7),HPI!$A$27:$G$36,6,FALSE) -> #N/A | O3: =VLOOKUP(($C$7),HPI!$A$27:$G$36,7,FALSE) -> #N/A | P3: =INDEX(B27:G36,MATCH($C$7,A27:A36,0),MATCH($J$2,B26:G26,0)) -> #N/A
A4: Gross Loan | C4: =Gross_Loan -> #N/A | I4: Predicted Value: | J4: =INDEX(HPI!$B$14:$B$23,MATCH($C$7,HPI!$A$14:$A$23,0)) -> #N/A | K4: =INDEX(HPI!$C$14:$C$23,MATCH($C$7,HPI!$A$14:$A$23,0)) -> #N/A | L4: =INDEX(HPI!$C$14:$C$23,MATCH($C$7,HPI!$A$14:$A$23,0)) -> #N/A | M4: =INDEX(HPI!$D$14:$D$23,MATCH($C$7,HPI!$A$14:$A$23,0)) -> #N/A | N4: =INDEX(HPI!$D$14:$D$23,MATCH($C$7,HPI!$A$14:$A$23,0)) -> #N/A | O4: =INDEX(HPI!$E$14:$E$23,MATCH($C$7,HPI!$A$14:$A$23,0)) -> #N/A
A5: Net Loan | C5: ='BTL Calculator'!M158 -> 0 | I5: Predicted LTV Net Loan: | J5: =$C$5/HPIAdjusted2021 -> #N/A | K5: =$C$5/HPIAdjusted2022 -> #N/A | L5: =$C$5/HPIAdjusted2023 -> #N/A | M5: =$C$5/HPIAdjusted2024 -> #N/A | N5: =$C$5/HPIAdjusted2025 -> #N/A | O5: =$C$5/HPIAdjusted5yrTotal -> #N/A
A6: Net Loan used | C6: =NetLoanUsed -> #N/A | I6: Predicted LTV Net Loan Used: | J6: =$C$6/HPIAdjusted2021 -> #N/A | K6: =$C$6/HPIAdjusted2022 -> #N/A | L6: =$C$6/HPIAdjusted2023 -> #N/A | M6: =$C$6/HPIAdjusted2024 -> #N/A | N6: =$C$6/HPIAdjusted2025 -> #N/A | O6: =$C$6/HPIAdjusted5yrTotal -> #N/A
A7: Region Selected | C7: ='KB_CRITERIA AND CALCULATION '!D21 -> 0 | I7: Predicted LTV Gross Loan: | J7: =$C$4/HPIAdjusted2021 -> #N/A | K7: =$C$4/HPIAdjusted2022 -> #N/A | L7: =$C$4/HPIAdjusted2023 -> #N/A | M7: =$C$4/HPIAdjusted2024 -> #N/A | N7: =$C$4/HPIAdjusted2025 -> #N/A | O7: =C4/HPIAdjusted5yrTotal -> #N/A
A8: Monthly Rent | C8: ='KB_CRITERIA AND CALCULATION '!U22 -> 0 | I8: Predicted rental growth for region: | J8: =VLOOKUP(($C$7),Future_Rent_TBL,2,FALSE) -> #N/A | K8: =VLOOKUP(($C$7),Future_Rent_TBL,3,FALSE) -> #N/A | L8: =VLOOKUP(($C$7),Future_Rent_TBL,4,FALSE) -> #N/A | M8: =VLOOKUP(($C$7),Future_Rent_TBL,5,FALSE) -> #N/A | N8: =VLOOKUP(($C$7),Future_Rent_TBL,6,FALSE) -> #N/A | O8: =VLOOKUP(($C$7),Future_Rent_TBL,7,FALSE) -> #N/A
A9: ICR used in calculations | C9: ='KB_CRITERIA AND CALCULATION '!$W$90 -> - | I9: Predicted Rental Value: | J9: =INDEX(Adjusted_House_Price_TBL2[2021],MATCH($C$7,Adjusted_House_Price_TBL2[Column1],0)) -> #N/A | K9: =INDEX(Adjusted_House_Price_TBL2[2022],MATCH($C$7,Adjusted_House_Price_TBL2[Column1],0)) -> #N/A | L9: =INDEX(Adjusted_House_Price_TBL2[2022],MATCH($C$7,Adjusted_House_Price_TBL2[Column1],0)) -> #N/A | M9: =INDEX(Adjusted_House_Price_TBL2[2023],MATCH($C$7,Adjusted_House_Price_TBL2[Column1],0)) -> #N/A | N9: =INDEX(Adjusted_House_Price_TBL2[2023],MATCH($C$7,Adjusted_House_Price_TBL2[Column1],0)) -> #N/A | O9: =INDEX(Adjusted_House_Price_TBL2[2024],MATCH($C$7,Adjusted_House_Price_TBL2[Column1],0)) -> #N/A
I10: Predicted Rent Change (Total ICR) | J10: ='KB_CRITERIA AND CALCULATION '!$W$90 -> - | K10: =J10*(100%+K$8) -> #VALUE! | L10: =K10*(100%+L$8) -> #VALUE! | M10: =L10*(100%+M$8) -> #VALUE! | N10: =M10*(100%+N$8) -> #VALUE! | O10: =N10*(100%+O$8) -> #VALUE!
A11: HPI Data | I11: RENT DATA
A12: Outputs: impact on inputted house price in future years | I12: Outputs: impact on estmated monthly rent in future years
A13: Column1 | B13: 2021 | C13: 2022 | D13: 2023 | E13: 2024 | F13: 2025 | G13: 5yrs to 2025 | I13: Column1 | J13: 2021 | K13: 2022 | L13: 2023 | M13: 2024 | N13: 2025 | O13: 5yrs to 2025
A14: London | B14: =$C$3 -> 0 | C14: =B14*(100%+C27) -> 0 | D14: =C14*(100%+D27) -> 0 | E14: =D14*(100%+E27) -> 0 | F14: =E14*(100%+F27) -> 0 | G14: =B14*(100%+G27) -> 0 | I14: London | J14: =$C$8 -> 0 | K14: =J14*(100%+K27) -> 0 | L14: =K14*(100%+L27) -> 0 | M14: =L14*(100%+M27) -> 0 | N14: =M14*(100%+N27) -> 0 | O14: =J14*(100%+O27) -> 0
A15: South East | B15: =$C$3 -> 0 | C15: =B15*(100%+C28) -> 0 | D15: =C15*(100%+D28) -> 0 | E15: =D15*(100%+E28) -> 0 | F15: =E15*(100%+F28) -> 0 | G15: =B15*(100%+G28) -> 0 | I15: South East | J15: =$C$8 -> 0 | K15: =J15*(100%+K28) -> 0 | L15: =K15*(100%+L28) -> 0 | M15: =L15*(100%+M28) -> 0 | N15: =M15*(100%+N28) -> 0 | O15: =J15*(100%+O28) -> 0
A16: East | B16: =$C$3 -> 0 | C16: =B16*(100%+C29) -> 0 | D16: =C16*(100%+D29) -> 0 | E16: =D16*(100%+E29) -> 0 | F16: =E16*(100%+F29) -> 0 | G16: =B16*(100%+G29) -> 0 | I16: East | J16: =$C$8 -> 0 | K16: =J16*(100%+K29) -> 0 | L16: =K16*(100%+L29) -> 0 | M16: =L16*(100%+M29) -> 0 | N16: =M16*(100%+N29) -> 0 | O16: =J16*(100%+O29) -> 0
A17: South West | B17: =$C$3 -> 0 | C17: =B17*(100%+C30) -> 0 | D17: =C17*(100%+D30) -> 0 | E17: =D17*(100%+E30) -> 0 | F17: =E17*(100%+F30) -> 0 | G17: =B17*(100%+G30) -> 0 | I17: South West | J17: =$C$8 -> 0 | K17: =J17*(100%+K30) -> 0 | L17: =K17*(100%+L30) -> 0 | M17: =L17*(100%+M30) -> 0 | N17: =M17*(100%+N30) -> 0 | O17: =J17*(100%+O30) -> 0
A18: East Midlands | B18: =$C$3 -> 0 | C18: =B18*(100%+C31) -> 0 | D18: =C18*(100%+D31) -> 0 | E18: =D18*(100%+E31) -> 0 | F18: =E18*(100%+F31) -> 0 | G18: =B18*(100%+G31) -> 0 | I18: East Midlands | J18: =$C$8 -> 0 | K18: =J18*(100%+K31) -> 0 | L18: =K18*(100%+L31) -> 0 | M18: =L18*(100%+M31) -> 0 | N18: =M18*(100%+N31) -> 0 | O18: =J18*(100%+O31) -> 0
A19: West Midlands | B19: =$C$3 -> 0 | C19: =B19*(100%+C32) -> 0 | D19: =C19*(100%+D32) -> 0 | E19: =D19*(100%+E32) -> 0 | F19: =E19*(100%+F32) -> 0 | G19: =B19*(100%+G32) -> 0 | I19: West Midlands | J19: =$C$8 -> 0 | K19: =J19*(100%+K32) -> 0 | L19: =K19*(100%+L32) -> 0 | M19: =L19*(100%+M32) -> 0 | N19: =M19*(100%+N32) -> 0 | O19: =J19*(100%+O32) -> 0
A20: North East | B20: =$C$3 -> 0 | C20: =B20*(100%+C33) -> 0 | D20: =C20*(100%+D33) -> 0 | E20: =D20*(100%+E33) -> 0 | F20: =E20*(100%+F33) -> 0 | G20: =B20*(100%+G33) -> 0 | I20: North East | J20: =$C$8 -> 0 | K20: =J20*(100%+K33) -> 0 | L20: =K20*(100%+L33) -> 0 | M20: =L20*(100%+M33) -> 0 | N20: =M20*(100%+N33) -> 0 | O20: =J20*(100%+O33) -> 0
A21: Yorks & Humber | B21: =$C$3 -> 0 | C21: =B21*(100%+C34) -> 0 | D21: =C21*(100%+D34) -> 0 | E21: =D21*(100%+E34) -> 0 | F21: =E21*(100%+F34) -> 0 | G21: =B21*(100%+G34) -> 0 | I21: Yorks & Humber | J21: =$C$8 -> 0 | K21: =J21*(100%+K34) -> 0 | L21: =K21*(100%+L34) -> 0 | M21: =L21*(100%+M34) -> 0 | N21: =M21*(100%+N34) -> 0 | O21: =J21*(100%+O34) -> 0
A22: North West | B22: =$C$3 -> 0 | C22: =B22*(100%+C35) -> 0 | D22: =C22*(100%+D35) -> 0 | E22: =D22*(100%+E35) -> 0 | F22: =E22*(100%+F35) -> 0 | G22: =B22*(100%+G35) -> 0 | I22: North West | J22: =$C$8 -> 0 | K22: =J22*(100%+K35) -> 0 | L22: =K22*(100%+L35) -> 0 | M22: =L22*(100%+M35) -> 0 | N22: =M22*(100%+N35) -> 0 | O22: =J22*(100%+O35) -> 0
A23: Wales | B23: =$C$3 -> 0 | C23: =B23*(100%+C36) -> 0 | D23: =C23*(100%+D36) -> 0 | E23: =D23*(100%+E36) -> 0 | F23: =E23*(100%+F36) -> 0 | G23: =B23*(100%+G36) -> 0 | I23: Wales | J23: =$C$8 -> 0 | K23: =J23*(100%+K36) -> 0 | L23: =K23*(100%+L36) -> 0 | M23: =L23*(100%+M36) -> 0 | N23: =M23*(100%+N36) -> 0 | O23: =J23*(100%+O36) -> 0
A25: Source Taken: | I25: Source Data: Savills Forecast Rent Changes Feb 2021 - CAPPED TO: | O25: 0.02
A26: Column1 | B26: 2021 | C26: 2022 | D26: 2023 | E26: 2024 | F26: 2025 | G26: 5yrs to 2025 | I26: Column1 | J26: 2021 | K26: 2022 | L26: 2023 | M26: 2024 | N26: 2025 | O26: 5yrs to 2025
A27: London | B27: 0.07 | C27: 0.02 | D27: 0.015 | E27: 0.01 | F27: 0.005 | G27: 0.124 | I27: London | J27: =MIN(J41,$O$25) -> 0.015 | K27: =MIN(K41,$O$25) -> 0.02 | L27: =MIN(L41,$O$25) -> 0.02 | M27: =MIN(M41,$O$25) -> 0.02 | N27: =MIN(N41,$O$25) -> 0.02 | O27: 0.193
A28: South East | B28: 0.09 | C28: 0.03 | D28: 0.025 | E28: 0.02 | F28: 0.015 | G28: 0.191 | I28: Outside London | J28: =MIN(J42,$O$25) -> 0.005 | K28: =MIN(K42,$O$25) -> 0.02 | L28: =MIN(L42,$O$25) -> 0.02 | M28: =MIN(M42,$O$25) -> 0.02 | N28: =MIN(N42,$O$25) -> 0.02 | O28: 0.159
A29: East | B29: 0.08 | C29: 0.03 | D29: 0.025 | E29: 0.02 | F29: 0.015 | G29: 0.18 | I29: South East | J29: =MIN(J43,$O$25) -> 0.005 | K29: =MIN(K43,$O$25) -> 0.02 | L29: =MIN(L43,$O$25) -> 0.02 | M29: =MIN(M43,$O$25) -> 0.02 | N29: =MIN(N43,$O$25) -> 0.02 | O29: =$O$28 -> 0.159
A30: South West | B30: 0.085 | C30: 0.035 | D30: 0.03 | E30: 0.025 | F30: 0.02 | G30: 0.209 | I30: East | J30: =MIN(J44,$O$25) -> 0.005 | K30: =MIN(K44,$O$25) -> 0.02 | L30: =MIN(L44,$O$25) -> 0.02 | M30: =MIN(M44,$O$25) -> 0.02 | N30: =MIN(N44,$O$25) -> 0.02 | O30: =$O$28 -> 0.159
A31: East Midlands | B31: 0.09 | C31: 0.04 | D31: 0.035 | E31: 0.03 | F31: 0.025 | G31: 0.239 | I31: South West | J31: =MIN(J45,$O$25) -> 0.005 | K31: =MIN(K45,$O$25) -> 0.02 | L31: =MIN(L45,$O$25) -> 0.02 | M31: =MIN(M45,$O$25) -> 0.02 | N31: =MIN(N45,$O$25) -> 0.02 | O31: =$O$28 -> 0.159
A32: West Midlands | B32: 0.09 | C32: 0.04 | D32: 0.035 | E32: 0.03 | F32: 0.025 | G32: 0.239 | I32: East Midlands | J32: =MIN(J46,$O$25) -> 0.005 | K32: =MIN(K46,$O$25) -> 0.02 | L32: =MIN(L46,$O$25) -> 0.02 | M32: =MIN(M46,$O$25) -> 0.02 | N32: =MIN(N46,$O$25) -> 0.02 | O32: =$O$28 -> 0.159
A33: North East | B33: 0.08 | C33: 0.04 | D33: 0.035 | E33: 0.035 | F33: 0.03 | G33: 0.239 | I33: West Midlands | J33: =MIN(J47,$O$25) -> 0.005 | K33: =MIN(K47,$O$25) -> 0.02 | L33: =MIN(L47,$O$25) -> 0.02 | M33: =MIN(M47,$O$25) -> 0.02 | N33: =MIN(N47,$O$25) -> 0.02 | O33: =$O$28 -> 0.159
A34: Yorks & Humber | B34: 0.105 | C34: 0.045 | D34: 0.04 | E34: 0.035 | F34: 0.03 | G34: 0.28 | I34: North East | J34: =MIN(J48,$O$25) -> 0.005 | K34: =MIN(K48,$O$25) -> 0.02 | L34: =MIN(L48,$O$25) -> 0.02 | M34: =MIN(M48,$O$25) -> 0.02 | N34: =MIN(N48,$O$25) -> 0.02 | O34: =$O$28 -> 0.159
A35: North West | B35: 0.105 | C35: 0.045 | D35: 0.04 | E35: 0.035 | F35: 0.03 | G35: 0.28 | I35: Yorks & Humber | J35: =MIN(J49,$O$25) -> 0.005 | K35: =MIN(K49,$O$25) -> 0.02 | L35: =MIN(L49,$O$25) -> 0.02 | M35: =MIN(M49,$O$25) -> 0.02 | N35: =MIN(N49,$O$25) -> 0.02 | O35: =$O$28 -> 0.159
A36: Wales | B36: 0.1 | C36: 0.04 | D36: 0.04 | E36: 0.035 | F36: 0.03 | G36: 0.268 | I36: North West | J36: =MIN(J50,$O$25) -> 0.005 | K36: =MIN(K50,$O$25) -> 0.02 | L36: =MIN(L50,$O$25) -> 0.02 | M36: =MIN(M50,$O$25) -> 0.02 | N36: =MIN(N50,$O$25) -> 0.02 | O36: =$O$28 -> 0.159
I37: Wales | J37: =MIN(J51,$O$25) -> 0.005 | K37: =MIN(K51,$O$25) -> 0.02 | L37: =MIN(L51,$O$25) -> 0.02 | M37: =MIN(M51,$O$25) -> 0.02 | N37: =MIN(N51,$O$25) -> 0.02 | O37: =$O$28 -> 0.159
A39: Source Data: Savills Forecast HPI Changes August 2021 | I39: Source Data: Savills Forecast Rent Changes Feb 2021
A40: Column1 | B40: 2021 | C40: 2022 | D40: 2023 | E40: 2024 | F40: 2025 | G40: 5yrs to 2025 | I40: Column1 | J40: 2021 | K40: 2022 | L40: 2023 | M40: 2024 | N40: 2025 | O40: 5yrs to 2025
A41: London | B41: 0.07 | C41: 0.02 | D41: 0.015 | E41: 0.01 | F41: 0.005 | G41: 0.124 | I41: London | J41: 0.015 | K41: 0.055 | L41: 0.04 | M41: 0.035 | N41: 0.035 | O41: 0.193
A42: South East | B42: 0.09 | C42: 0.03 | D42: 0.025 | E42: 0.02 | F42: 0.015 | G42: 0.191 | I42: Outside London | J42: 0.005 | K42: 0.04 | L42: 0.035 | M42: 0.035 | N42: 0.035 | O42: 0.159
...

Sheet Fusion Calc
B3: BBR | C3: 0.04
A4: Standard | B4: Rate | C4: Rate with BBR | D4: Product Fee | E4: Monthly Interest rate | F4: Pay rate | G4: Revert rate | H4: LTV | I4: Max Loan | J4: Min Loan | K4: Max Loan for Property | L4: Max Gross Loan Capped | M4: Max Gross Loan | N4: Max Net Loan | O4: Rolled Month Interest | P4: Rent with Top Slicing | Q4: Defer Int £ | R4: Serviced Interest | S4: Initial Pay rate ICR | T4: Stressed ICR | U4: Product Fee | V4: Total Payrate Interest | W4: Actual ICR | X4: Total Product Fee | Y4: NPB Net Loan + max 2% fee | Z4: Monthly DD | AA4: Cost of Borrowing | AB4: Monthy Interest Cost | AC4: Revert Rate | AD4: Revert Period DD & ICR
A5: Residentials | B5: 0.0479 | C5: =SUM($C$3,B5) -> 0.0879 | D5: 0.02 | E5: =C5/12 -> 0.007325 | F5: 0.007325 | H5: 0.75 | I5: 3000000 | J5: 100000 | K5: =MIN(H5*Property_Value,I5) -> 0 | L5: =ROUND(MIN(M5,K5),0) -> 0 | M5: =P5/(F5*(24-'BTL Calculator'!$R$81)*'Fusion Calc'!S5) -> 0 | N5: =L5-U5-Q5-O5 -> 0 | O5: =L5*'BTL Calculator'!$R$81*(F5) -> 0 | P5: =('BTL Calculator'!$V$9+'BTL Calculator'!$R$80)*24 -> 0 | Q5: =(L5*'BTL Calculator'!$S$81/12)*24 -> 0 | R5: =L5*C5*(24-'BTL Calculator'!$R$81)/12 -> 0 | S5: 1.1 | T5: NA | U5: =L5*D5 -> 0 | V5: =M5*F5*24 -> 0 | W5: =P5/(((F5*12)*L5*2)-O5) -> #DIV/0!
A6: Semi and Comm | B6: 0.0529 | C6: =SUM($C$3,B6) -> 0.0929 | D6: 0.02 | E6: =C6/12 -> 0.0077416667 | F6: 0.0077416667 | H6: 0.7 | I6: 3000000 | J6: 100000 | K6: =MIN(H6*Property_Value,I6) -> 0 | L6: =MIN(M6,K6) -> 0 | M6: =P6/(F6*(24-'BTL Calculator'!$R$81)*'Fusion Calc'!S6) -> 0 | N6: =L6-U6-Q6-O6 -> 0 | O6: =L6*'BTL Calculator'!$R$81*(F6) -> 0 | P6: =('BTL Calculator'!$V$9+'BTL Calculator'!$R$80)*24 -> 0 | Q6: =(L6*'BTL Calculator'!$S$81/12)*24 -> 0 | R6: =L6*C6*(24-'BTL Calculator'!$R$81)/12 -> 0 | S6: 1.1 | T6: NA | U6: =L6*D6 -> 0 | V6: =M6*F6*24 -> 0 | W6: =P6/(((F6*12)*L6*2)-O6) -> #DIV/0!
A8: Large Loans | B8: Rate | C8: Rate with BBR | D8: Product Fee | G8: Revert Rate | H8: LTV | I8: Max Loan | J8: Min Loan
A9: Residentials | B9: 0.0599 | C9: =SUM($C$3,B9) -> 0.0999 | D9: 0.02 | E9: =C9/12 -> 0.008325 | F9: 0.008325 | H9: 0.75 | I9: 20000000 | J9: 3000000 | K9: =MIN(H9*Property_Value,I9) -> 0 | L9: =MIN(M9,K9) -> 0 | M9: =P9/(F9*(24-'BTL Calculator'!$R$81)*'Fusion Calc'!S9) -> 0 | N9: =L9-U9-Q9-O9 -> 0 | O9: =L9*'BTL Calculator'!$R$81*(F9) -> 0 | P9: =('BTL Calculator'!$V$9+'BTL Calculator'!$R$80)*24 -> 0 | Q9: =(L9*'BTL Calculator'!$S$81/12)*24 -> 0 | R9: =L9*C9*(24-'BTL Calculator'!$R$81)/12 -> 0 | S9: 1.1 | T9: NA | U9: =L9*D9 -> 0 | V9: =M9*F9*24 -> 0 | W9: =P9/(((F9*12)*L9*2)-O9) -> #DIV/0!
A10: Semi and Comm | B10: 0.0649 | C10: =SUM($C$3,B10) -> 0.1049 | D10: 0.02 | E10: =C10/12 -> 0.0087416667 | F10: 0.0087416667 | H10: 0.7 | I10: 20000000 | J10: 3000000 | K10: =MIN(H10*Property_Value,I10) -> 0 | L10: =MIN(M10,K10) -> 0 | M10: =P10/(F10*(24-'BTL Calculator'!$R$81)*'Fusion Calc'!S10) -> 0 | N10: =L10-U10-Q10-O10 -> 0 | O10: =L10*'BTL Calculator'!$R$81*(F10) -> 0 | P10: =('BTL Calculator'!$V$9+'BTL Calculator'!$R$80)*24 -> 0 | Q10: =(L10*'BTL Calculator'!$S$81/12)*24 -> 0 | R10: =L10*C10*(24-'BTL Calculator'!$R$81)/12 -> 0 | S10: 1.1 | T10: NA | U10: =L10*D10 -> 0 | V10: =M10*F10*24 -> 0 | W10: =P10/(((F10*12)*L10*2)-O10) -> #DIV/0!

Sheet KB_CRITERIA AND CALCULATION 
B1: Funding Lines
D2: Loan Chosen | E2: Zircon Limit | H2: Pearl Limit | K2: =_xlfn.TEXTJOIN(" or ",TRUE,F3,I3) -> Zircon or Pearl | L2: =IF(K2="","No Funding lines available","Available Funding lines are: "&K2) -> Available Funding lines are: Zircon or Pearl | M2: Notes
E3: Zircon | F3: =IF(COUNTIF(F4:F12,0)=0,E3,"") -> Zircon | G3: =IF(_xlfn.TEXTJOIN(", ",TRUE,G4:G12)="","",E3&" not available due to - "&_xlfn.TEXTJOIN(", ",TRUE,G4:G12)) -> #N/A | H3: Pearl | I3: =IF(COUNTIF(I4:I12,0)=0,H3,"") -> Pearl | J3: =IF(_xlfn.TEXTJOIN(", ",TRUE,J4:J12)="","",H3&" not available due to - "&_xlfn.TEXTJOIN(", ",TRUE,J4:J12)) -> #N/A | K3: =_xlfn.TEXTJOIN(" ",TRUE,G3,J3) -> #N/A | L3: =IF(K3="","",IF(L2="",""," ")&K3) -> #N/A
C4: deferred interest | D4: =J90 -> #N/A | E4: 0.01 | F4: =IF($D4>E4,0,1) -> #N/A | G4: =IF(F4=0,"Deferred Interest too High","") -> #N/A | H4: ='Product Data'!$P$9 -> 0.02 | I4: =IF($D4>H4,0,1) -> #N/A | J4: =IF(I4=0,"Deferred Interest too High","") -> #N/A | M4: IF deferred interest > 1%, only PBL YES | V4: PBL terms are:
C5: Rolled Months | D5: =K90 -> #N/A | E5: 6 | F5: =IF($D5>E5,0,1) -> #N/A | G5: =IF(F5=0,"Rolled Months too High","") -> #N/A | H5: ='BTL Calculator'!#REF! -> #REF! | I5: =IF($D5>H5,0,1) -> #N/A | J5: =IF(I5=0,"Rolled Months too High","") -> #N/A | M5: IF rolled up months > 6, only PBL YES | V5: 2yr: 24+up to 12m servicer permitted extension (at the 24m stage, and only once) YES
C6: Term | D6: =Term -> 24 | E6: 36 | F6: =IF($D6>E6,0,1) -> 1 | G6: =IF(F6=0,"Term too High","") | H6: 36 | I6: =IF($D6>H6,0,1) -> 1 | J6: =IF(I6=0,"Term too High","") | M6: IF initial term > 24 months, PBL only (as their loan facility is a proper 3yr term, not a 2+1) YES | V6: 3yr: 36m + 3m servicer extension YES
C7: Interest Rate | D7: ='BTL Calculator'!M141 -> #N/A | E7: 0.0499 | F7: =IF($D7<E7,0,1) -> #N/A | G7: =IF(F7=0,"Interest Rate too low","") -> #N/A | H7: 0 | I7: =IF($D7<H7,0,1) -> #N/A | J7: =IF(I7=0,"Interest Rate too low","") -> #N/A | M7: IF initial interest rate is < 4.99%, then PBL only (ZBL have min 4.99%) YES currently we are funding loans at 4.79% which is outside ZBL criteria | U7: Do you agree, or are there more? I have to check what’s the minimum interest rate to be charged per month on PBL as currently ZBL is 0.41% with 4.79% this become 0.399% per month | V7: During the extension, interest is due at the FULL interest rate, not the pay rate YES
C8: ICR | D8: ='BTL Calculator'!M155 -> - | E8: 1 | F8: =IF($D8<E8,0,1) -> 1 | G8: =IF(F8=0,"ICR too Low","") | H8: 1 | I8: =IF($D8<H8,0,1) -> 1 | J8: =IF(I8=0,"ICR too Low","") | M8: IF ICR, on an exception, goes below 100%, then ZBL only (old methodology, 80%+ where other income/wealth can support) Agreed – we must ensure ICR is 100% or above on all loans, PBL To be finalised | V8: ZBL terms are:
C9: Country | D9: ='BTL Calculator'!V16 -> No | F9: =IF(D9="No",1,0) -> 1 | G9: =IF(F9=0,"Restricted Country","") | H9: ANY | I9: 1 | J9: =IF(I9=0,"Restricted Country","") | M9: IF country on the excluded list for ZBL (below), then PBL only YES ,for PBL as long is not a restricted country Afghanistan, Bosnia Herzegovina, Burundi, Central African Republic, Cuba, Democratic People's Republic of Korea, Democratic Republic of the Congo, Eritrea, Ethiopia, Iran (Islamic Republic of), Iraq, Laos People's Democratic Republic, Libyan Arab Jamahiriya, Myanmar, Pakistan, Somalia, South Sudan, Sudan, Syrian Arab Republic, Uganda, Vanuatu, Venezuela, Yemen. | U9: FYI – the ERC is basically waived after 60 days (3+ yr loan) and 30 days for 2yr loan. Agreed Even during the extension. This is fine – you only really extend when a small delay in exit, and it’s at full interest rate so can be penal compared to a 3yr (to avoid gaming). We will also have retention products then to try to lock them in again | V9: 2yr: 24+up to 3m servicer permitted extension. During the extension, interest is due at the FULL interest rate, not the pay rate serviceable on full IR, however ZBL allows extension upto 12months
C10: Max Loan | D10: =Gross_Loan -> #N/A | E10: 3000000 | F10: =IF($D10>E10,0,1) -> #N/A | G10: =IF(F10=0,"Loan too big","") -> #N/A | H10: 3000000 | I10: =IF($D10>H10,0,1) -> #N/A | J10: =IF(I10=0,"Loan too big","") -> #N/A | M10: QUESTION: is the max individual loan on PBL £3m, TBD , await lender confirmation like it is on ZBL? ZBL specifically calls it out, but PBL just has standard ‘£4m’ for single property loan there will be some covenant set by PBL Lender which we are finalising terms on max amount | U10: · An early repayment charge (ERC) is payable if the Borrower redeems the loan before the contractual maturity date of the loan. ERC is waived for any early redemptions that occur within a grace period starting from a maximum of 60 days prior to the original contractual maturity date and continuing thereafter (including during any Servicer Extension). Does this cover if redeemed on month 22? | V10: 3yr: 24+up to 12m servicer permitted extension. We grant this automatically subject to conditions. Whilst the contract states interest due at full rate, we’ve done the upfront calculations that the deferred interest/net loan means reduced payments to not impact LTV adversely , pls discuss as currently UW are deferring interest upto 36m by issuing 24m term +12m (extension ), hence the issue we had today, with this the serviceable interest from 24m to 36m become serviceable on pay rate, 4.79% rate deferred 0.50% for 36m with 2 month rolled up , the borrow is serving interest on deferred rate for 34m at 4.29% -
C11: Holiday Let | D11: =D40 -> No | F11: 1 | G11: =IF(F11=0,"Term too High","") | H11: No | I11: =IF($D11=H11,1,0) -> 1 | J11: =IF(I11=0,C11,"")
F12: =IF($D12>E12,0,1) -> 1 | G12: =IF(F12=0,"Term too High","") | I12: =IF($D12>H12,0,1) -> 1
B18: Loan Calculations & Summary | F18: Linked/taken from main ICR calculator
B19: Property Details | S19: ='BTL Calculator'!V8 -> 0 | U19: ='BTL Calculator'!V9 -> 0 | W19: ='BTL Calculator'!V11 -> 0 | X19: ='BTL Calculator'!V9+'BTL Calculator'!V11 -> 0
C20: Property postcode | D20: ='BTL Calculator'!V14 -> 0 | F20: =LEFT(D20,2-(--ISNUMBER(MID(D20,2,1)*1))) -> 0 | K20: Proc Fee | L20: =D28*Gross_Loan -> #N/A | S20: Rent charge | U20: Rent charge | V20: Top Slice
C21: Property Region: | D21: ='BTL Calculator'!V15 -> 0 | F21: =INDEX('Product Data'!$I$220:$I$326,MATCH(F20,'Product Data'!$B$220:$B$334,0)) -> #N/A | I21: APRC Calculator after Rolled | S21: Weekly | U21: =IF($S$19=$S$21,$U$19,U23/52) -> 0 | V21: =V23/52 -> 0 | W21: =IF($S$19=$S$21,$W$19,W23/52) -> 0
C22: APRC Calculator before Rolled | I22: Gross Loan Amount | L22: =(IF(RoundDown,R90,Q90)) -> #N/A | S22: Monthly | U22: =IF($S$19=$S$22,U19,U23/12) -> 0 | V22: ='BTL Calculator'!$L$80 -> 0 | W22: =IF($S$19=$S$22,W19,W23/12) -> 0 | X22: =IF($S$19=$S$22,X19,X23/12)+'BTL Calculator'!H14 -> 0 | AB22: APRC Calculator after Rolled | AI22: APRC Calculator after Rolled | AN22: APRC Calculator after Rolled
C23: Gross Loan Amount | D23: =(IF(RoundDown,R90,Q90)) -> #N/A | I23: Duration (Months) | L23: =Term -> 24 | S23: Annual | U23: =IF($S$19=$S$23,U19,IF($S$19=$S$21,U19*52,U19*12)) -> 0 | V23: =V22*12 -> 0 | W23: =IF($S$19=$S$23,$W$19,IF($S$19=$S$21,W19*52,W19*12)) -> 0 | X23: =IF($S$19=$S$23,X19,IF($S$19=$S$21,X19*52,X19*12)) -> 0 | AB23: Gross Loan Amount | AC23: =(IF(RoundDown,R108,Q108)) -> #N/A | AI23: Gross Loan Amount | AJ23: =(IF(RoundDown,R126,Q126)) -> #N/A | AN23: Gross Loan Amount | AO23: =(IF(RoundDown,R144,Q144)) -> #N/A
C24: Duration (Months) | D24: =Term -> 24 | I24: Rolled | L24: =RollupMonths -> #N/A | M24: =$AE$90 -> #N/A | S24: Term rent | U24: =Monthly_Rent*Term -> 0 | V24: =V22*Term -> 0 | W24: =W22*24 -> 0 | AB24: Duration (Months) | AC24: =Term -> 24 | AI24: Duration (Months) | AJ24: =Term -> 24 | AN24: Duration (Months) | AO24: =Term -> 24
C25: Rolled | D25: 0 | I25: Monthly Int Rate | L25: =IFERROR((Tier_Standard_rate-DeferedIntPercent)/12,"-") -> - | M25: =IFERROR(L22*L25,"-") -> - | AB25: Rolled | AC25: =K108 -> #N/A | AI25: Rolled | AJ25: =K126 -> #N/A | AN25: Rolled | AO25: =K144 -> #N/A
C26: Monthly Int Rate | D26: =IFERROR(Tier_Standard_rate/12,"-") -> - | F26: =IFERROR(D23*D26,"-") -> - | I26: Defered interest | L26: =DeferedIntPercent/12 -> #N/A | M26: =L22*L26*Term -> #N/A | AB26: Monthly Int Rate | AC26: =IFERROR((H108-J108)/12,"-") -> - | AE26: =AE108 -> #N/A | AI26: Monthly Int Rate | AJ26: =IFERROR((H126-J126)/12,"-") -> - | AL26: =AE126 -> #N/A | AN26: Monthly Int Rate | AO26: =IFERROR((H144-J144)/12,"-") -> - | AQ26: =AE144 -> #N/A
C27: Product fee % | D27: =Prod_Fee_Chosen -> #N/A | F27: =D23*D27 -> #N/A | I27: Product fee % | L27: =Prod_Fee_Chosen -> #N/A | M27: =L22*L27 -> #N/A | AB27: Defered interest | AC27: =J108/12 -> #N/A | AE27: =IFERROR(AC23*AC26,"-") -> - | AI27: Defered interest | AJ27: =J126/12 -> #N/A | AL27: =IFERROR(AJ23*AJ26,"-") -> - | AN27: Defered interest | AO27: =J144/12 -> #N/A | AQ27: =IFERROR(AO23*AO26,"-") -> -
C28: Proc Fee | D28: =IFERROR(IF('BTL Calculator'!H37>=0,'BTL Calculator'!H37,'BTL Calculator'!H36)+('BTL Calculator'!H38/D23),0) -> 0 | F28: =D23*D28 -> #N/A | G28: Core Net Loan LTV | I28: Proc Fee | L28: =D28 -> 0 | M28: =L22*L28 -> #N/A | AB28: Product fee % | AC28: =I108 -> #N/A | AE28: =AC23*AC27*Term -> #N/A | AI28: Product fee % | AJ28: =I126 -> #N/A | AL28: =AJ23*AJ27*Term -> #N/A | AN28: Product fee % | AO28: 0.03 | AQ28: =AO23*AO27*Term -> #N/A
C29: Net loan Amount | D29: =IFERROR(D23-(D23*D26*D25)-(D23*D27),"-") -> - | G29: =IFERROR(Core_Net_loan/Property_Value,"-") -> - | I29: Net loan Amount | L29: =IFERROR(L22-M27-M26-M24,"-") -> - | AB29: Proc Fee | AC29: =D28 -> 0 | AE29: =AC23*AC28 -> #N/A | AI29: Proc Fee | AJ29: =D28 -> 0 | AL29: =AJ23*AJ28 -> #N/A | AN29: Proc Fee | AO29: =D28 -> 0 | AQ29: =AO23*AO28 -> #N/A
C30: Total Int£ over term | D30: =IFERROR(D24*F26,"-") -> - | I30: Total Int£ over term | L30: =IFERROR(L23*M25+M26,"-") -> - | AB30: Net loan Amount | AC30: =IFERROR(AC23-AE29-AE28-AE26,"-") -> - | AE30: =AC23*AC29 -> #N/A | AI30: Net loan Amount | AJ30: =IFERROR(AJ23-AL29-AL28-AL26,"-") -> - | AL30: =AJ23*AJ29 -> #N/A | AN30: Net loan Amount | AO30: =IFERROR(AO23-AQ29-AQ28-AQ26,"-") -> -
C31: Total Int£ + Prodfee£ | D31: =IFERROR(D30+F27,"-") -> - | I31: Total Int£ + Prodfee£ | L31: =IFERROR(L30+M27,"-") -> - | AB31: Total Int£ over term | AC31: =IFERROR(AC24*AE27+AE28,"-") -> - | AI31: Total Int£ over term | AJ31: =IFERROR(AJ24*AL27+AL28,"-") -> - | AN31: Total Int£ over term | AO31: =IFERROR(AO24*AQ27+AQ28,"-") -> -
C32: APR | D32: =IFERROR(D31/D29/D24*12,"-") -> - | I32: APR | L32: =IFERROR(L31/L29/L23*12,"-") -> - | AB32: Total Int£ + Prodfee£ | AC32: =IFERROR(AC31+AE29,"-") -> - | AI32: Total Int£ + Prodfee£ | AJ32: =IFERROR(AJ31+AL29,"-") -> - | AN32: Total Int£ + Prodfee£ | AO32: =IFERROR(AO31+AQ29,"-") -> -
C33: Monthly APR | D33: =IFERROR(D32/12,"-") -> - | I33: Monthly APR | L33: =IFERROR(L32/12,"-") -> - | AB33: APR | AC33: =IFERROR(AC32/AC30/AC24*12,"-") -> - | AI33: APR | AJ33: =IFERROR(AJ32/AJ30/AJ24*12,"-") -> - | AN33: APR | AO33: =IFERROR(AO32/AO30/AO24*12,"-") -> -
AB34: Monthly APR | AC34: =IFERROR(AC33/12,"-") -> - | AI34: Monthly APR | AJ34: =IFERROR(AJ33/12,"-") -> - | AN34: Monthly APR | AO34: =IFERROR(AO33/12,"-") -> -
B35: Tier Selector & LTV | G35: Tier
A36: CRITERIA RESI | B36: Property | D36: =IFERROR(INDEX('Product Data'!B9:B12,MATCH(TEXT(F36&"*",),'Product Data'!B9:B12,0)),"N/A") -> 1) Standard BTL | E36: =VLOOKUP(D36,'Product Data'!B8:N12,13,0) -> Tier 1 | F36: =MAX(F37:F55,IF(AND(F44=3,F37+F38>2),4,0)) -> 1 | G36: 0 | H36: 1 | I36: 2 | J36: 3 | K36: 3 | L36: 3 | M36: 4 | N36: MAX LTV | O36: =MIN(O37:O42) -> 0.75 | P36: =MIN(P37:P42) -> 0.75 | Q36: =MIN(Q37:Q42) -> 0.75 | R36: =MIN(R37:R42) -> 0.7 | S36: =MIN(S37:S42) -> 0.75 | T36: CRITERIA FOR COMMERCIAL & SEMI COMMERCIAL | U36: Property | W36: =IFERROR(INDEX('Product Data'!B34:B35,MATCH(TEXT(Y36&"*",),'Product Data'!B34:B35,0)),"N/A") -> 1) Standard | X36: =VLOOKUP(W36,'Product Data'!B34:N35,13,0) -> Tier 1 | Y36: =MAX(Y37:Y52) -> 1 | Z36: 0 | AA36: 1 | AB36: 1 | AC36: 1 | AD36: 1 | AE36: 2 | AF36: 2
C37: HMO | D37: ='BTL Calculator'!$V$17 -> No | F37: =INDEX($G$36:$M$36,MATCH(D37,G37:M37,0)) -> 1 | H37: No | I37: =IF(ISNUMBER(SEARCH("Commercial",'BTL Calculator'!V3)),"<= 12 beds","<= 6 beds") -> <= 6 beds | L37: =IF(ISNUMBER(SEARCH("commercial",'BTL Calculator'!V3)),"> 12 beds","> 6 beds") -> > 6 beds | N37: LTV Tier Cap | O37: 0.75 | P37: 0.75 | Q37: 0.75 | R37: 0.7 | S37: =INDEX(O37:R37,MATCH($F$36,$O$38:$R$38,0)) -> 0.75 | V37: HMO | W37: ='BTL Calculator'!$V$17 -> No | Y37: =INDEX($Z$36:$AE$36,MATCH(W37,Z37:AE37,0)) -> 1 | AA37: No | AB37: =IF(Rate_Type="Tracker","<= 6 beds","No") -> No | AC37: <= 12 beds | AE37: > 12 beds
C38: Multi-Unit Freehold Block | D38: ='BTL Calculator'!$V$18 -> No | F38: =INDEX($G$36:$M$36,MATCH(D38,G38:M38,0)) -> 1 | H38: No | I38: =IF(ISNUMBER(SEARCH("Commercial",'BTL Calculator'!V3)),"<= 12 units","<= 6 units") -> <= 6 units | K38: <= 30 units | L38: =IF(ISNUMBER(SEARCH("commercial",'BTL Calculator'!V3)),"> 12 units",IF(Rate_Type="Tracker","<= 30 units","<= 10 units")) -> <= 10 units | M38: > 30 Units | O38: 1 | P38: 2 | Q38: 3 | R38: 4 | S38: Chosen | V38: Multi-Unit Freehold Block | W38: ='BTL Calculator'!$V$18 -> No | Y38: =INDEX($Z$36:$AF$36,MATCH(W38,Z38:AF38,0)) -> 1 | AA38: No | AB38: =IF(Rate_Type="Tracker","<= 6 units","No") -> No | AC38: <= 12 units | AE38: > 12 units
C39: Flats above Restricted commercial | D39: ='BTL Calculator'!$V$19 -> No | F39: =INDEX($G$36:$M$36,MATCH(D39,G39:M39,0)) -> 1 | H39: No | I39: Yes | O39: =O$37 -> 0.75 | P39: =P$37 -> 0.75 | Q39: =Q$37 -> 0.75 | R39: =R$37 -> 0.7 | S39: =INDEX(O39:R39,MATCH($F$36,$O$38:$R$38,0)) -> 0.75 | V39: Development Exit | W39: ='BTL Calculator'!$V$21 -> No | Y39: =INDEX($Z$36:$AF$36,MATCH(W39,Z39:AF39,0)) -> 1 | AA39: No | AE39: Yes
C40: Holiday/ Short term Let | D40: ='BTL Calculator'!$V$20 -> No | F40: =INDEX($G$36:$M$36,MATCH(D40,G40:M40,0)) -> 1 | H40: No | I40: No | L40: =IF('BTL Calculator'!V2="Core","","Yes") -> Yes | V40: PBSA/Serviced Accommodation? | W40: ='BTL Calculator'!$V$23 -> No | Y40: =INDEX($Z$36:$AF$36,MATCH(W40,Z40:AF40,0)) -> 1 | AA40: No | AB40: No | AC40: Yes | AE40: Yes
C41: Development Exit | D41: ='BTL Calculator'!$V$21 -> No | F41: =INDEX($G$36:$M$36,MATCH(D41,G41:M41,0)) -> 1 | H41: No | I41: Yes
C42: PBSA/Serviced Accommodation? | D42: ='BTL Calculator'!$V$23 -> No | F42: =INDEX($G$36:$M$36,MATCH(D42,G42:M42,0)) -> 1 | H42: No | I42: No | O42: =O$37 -> 0.75 | P42: =IF($D$39=$H$39,P37,60%) -> 0.75 | Q42: =IF($D$39=$I$39,70%,Q37) -> 0.75 | R42: =R$37 -> 0.7 | S42: =INDEX(O42:R42,MATCH($F$36,$O$38:$R$38,0)) -> 0.75 | U42: Customer
B43: Customer | V43: Commercial Owner Occuppied | W43: ='BTL Calculator'!H13 -> No | Y43: =INDEX($Z$36:$AF$36,MATCH(W43,Z43:AF43,0)) -> 1 | AA43: No | AE43: Yes
C44: First time Landlord | D44: ='BTL Calculator'!$H$12 -> No | F44: =INDEX($G$36:$M$36,MATCH(D44,G44:M44,0)) -> 1 | H44: No | I44: Yes | L44: =IF('BTL Calculator'!V2="Core","","Yes") -> Yes | V44: First time commercial Landlord | W44: ='BTL Calculator'!$H$12 -> No | Y44: =INDEX($Z$36:$AF$36,MATCH(W44,Z44:AF44,0)) -> 1 | AA44: No | AE44: Yes
C45: Expat/ Foreign National | D45: =IF(AND('BTL Calculator'!$H$15="Yes",'BTL Calculator'!$H$16="Yes"),"No",'BTL Calculator'!$H$15) -> No | F45: =INDEX($G$36:$M$36,MATCH(D45,G45:M45,0))+IF('BTL Calculator'!V2="Core",0,F46) -> 1 | G45: No | H45: No | I45: Yes | L45: =IF('BTL Calculator'!V2="Core","","Yes") -> Yes | V45: Expat/ Foreign National | W45: =IF(AND('BTL Calculator'!$H$15="Yes",'BTL Calculator'!$H$16="Yes"),"No",'BTL Calculator'!$H$15) -> No | Y45: =INDEX($Z$36:$AF$36,MATCH(W45,Z45:AF45,0)) -> 1 | AA45: No | AE45: Yes
...

Sheet BTL Calculator
H1: UNDERWRITER BTL Calculator | R1: Version 29 October 2025 | AP1: BDM? | AQ1: Messages | AR1: Term Radio Button | AS1: RADIO ROLLED | AU1: Radio Rolled vs Deferred | AZ1: Yes | BA1: No | BB1: Please Choose | BC1: Additional Settings | CH1: Tracker Rate 2% fee | CI1: Net Loan | CJ1: ='KB Model Suggestions Tr 2yr'!J9 -> #N/A | CK1: ='KB Model Suggestions Tr 2yr'!J3 -> #N/A
Q2: Specialist / Core | X2: =IF(V2="","<- Please select Specialist or Core","") -> <- Please select Specialist or Core | AA2: =IF(V2="Core",0,1) -> 1
F3: Input | H3: User Inputs | Q3: PRODUCT TYPE | X3: 0.75 | Y3: =IF(V3="Residential BTL","","Semi is mixed use, residential element is 50% or more. Commercial is over 50% commercial, or large residential blocks") -> Semi is mixed use, residential element is 50% or more. Commercial is over 50% commercial, or large residential blocks | Z3: =IF(OR(V3="Residential BTL",V3="Retention "),1,0) -> 0 | AA3: =IF(OR(V3="Residential BTL",V3="Retention "),1,0) -> 0 | AP3: Hide: Section 3 and row 150 onwards. Only include calc and holiday let tabs | AR3: 1 | AS3: 8 | CH3: Tracker Rate 4% fee | CI3: Net Loan | CJ3: ='KB Model Suggestions Tr 2yr'!F9 -> #N/A | CK3: ='KB Model Suggestions Tr 2yr'!F3 -> #N/A
CH4: Tracker Rate 6% fee | CI4: Net Loan | CJ4: ='KB Model Suggestions Tr 2yr'!B9 -> #N/A | CK4: ='KB Model Suggestions Tr 2yr'!B3 -> #N/A
Q5: Please select Range | X5: Max Gross Loan achieved on this product, for higher loan size refer to Fusion. | CH5: 2 Year Fixed Rate 2% fee | CI5: Net Loan | CJ5: ='KB V Model Suggestions Fixed 2'!J9 -> #N/A | CK5: ='KB V Model Suggestions Fixed 2'!J3 -> #N/A
CH6: 2 Year Fixed Rate 4% fee | CI6: Net Loan | CJ6: ='KB V Model Suggestions Fixed 2'!F9 -> #N/A | CK6: ='KB V Model Suggestions Fixed 2'!F3 -> #N/A
G7: Hubspot Loan Ref | H7: xxxxxxx | U7: Property Value | Y7: =IFERROR(IF(V3="Residential BTL","Rental Yield: "&TEXT(V9*12/Property_Value, "0.0%"),""),"") | CH7: 2 Year Fixed Rate 6% fee | CI7: Net Loan | CJ7: ='KB V Model Suggestions Fixed 2'!B9 -> #N/A | CK7: ='KB V Model Suggestions Fixed 2'!B3 -> #N/A
G8: Borrower Name | H8: xxxxxxx | Q8: Property | U8: Rent Charged | CH8: 3 Year Fixed Rate 2% fee | CX8: ="(Tracker Override) Deferred at full term? ("&Term&" months)" -> (Tracker Override) Deferred at full term? (24 months) | CY8: Default (Yes) | DA8: Can we remove highlighted fields now?
C9: Admin | U9: =IF(OR(V3="Residential BTL",V3="Retention "),"Estimated "&$V$8&" Gross Rent:","Estimated "&$V$8&" AST Rent:") -> Estimated AST Rent: | X9: Obtained from broker enquiry or AST if already rented | BB9: Basic | BE9: Fully R+D (Broker) | BH9: Fully R+D (Underwriter) | BJ9: Custom | CH9: 3 Year Fixed Rate 4% fee | CX9: (Tracker Override) Set rolled months to: | CY9: Default (Pay Rate) | DA9: Not sure lenvi will handle?
G10: Property Address | H10: xxxxxxx | U10: Estimated Monthly Gross Rent: | V10: =IF(V9="","",'KB_CRITERIA AND CALCULATION '!U22) | BA10: 0.06 | CH10: 3 Year Fixed Rate 6% fee | CX10: Borrower prefers interest to be: | CY10: Rolled
U11: =IF(OR(V3="Residential BTL",V3="Retention "),"","Estimated "&$V$8&" Commercial lease rent:") -> Estimated Commercial lease rent: | X11: =IFERROR("HPI Adjusted in 2022 "&TEXT(HPIAdjusted2022/1000000,"£ #0.##0")&"m, 2023 "&TEXT(HPIAdjusted2023/1000000,"£ #0.##0")&"m, 2024 "&TEXT(HPIAdjusted2024/1000000,"£ #0.##0")&"m, 2025 "&TEXT(HPIAdjusted2025/1000000,"£ #0.##0")&"m","") | AY11: Net Loan | BA11: Tier 1 | BB11: ='KB_CRITERIA AND CALCULATION '!AL112 -> 0 | BE11: ='KB_CRITERIA AND CALCULATION '!AL115 -> 0 | BH11: ='KB_CRITERIA AND CALCULATION '!AL118 -> 0 | BJ11: ='KB_CRITERIA AND CALCULATION '!AL115 -> 0 | CX11: Spread Rolled Months to reduce DD? | CY11: No
G12: =IF(OR(V3="Residential BTL",V3="Retention "),"First time Landlord?", "First time commercial Landlord") -> First time commercial Landlord | H12: No | U12: =IF(ISNUMBER(SEARCH("Commercial",V3)),"Estimated Monthly Gross Rent:","") | V12: =IF(V11="","",'KB_CRITERIA AND CALCULATION '!W22) | Y12: =IFERROR("Recommended from postcode - "&'KB_CRITERIA AND CALCULATION '!F21,"") | BA12: Tier 2 | BB12: ='KB_CRITERIA AND CALCULATION '!AL113 -> 0 | BE12: ='KB_CRITERIA AND CALCULATION '!AL116 -> 0 | BH12: ='KB_CRITERIA AND CALCULATION '!AL119 -> 0 | BJ12: ='KB_CRITERIA AND CALCULATION '!AL116 -> 0 | CX12: Round Gross Loan to Nearest £'000?
C13: Borrower | G13: =IF(OR(V3="Residential BTL",V3="Retention "),"","Commercial Owner Occuppied") -> Commercial Owner Occuppied | H13: No | V13: =IF(OR(V3="Residential BTL",V3 = "Retention "),"",('KB_CRITERIA AND CALCULATION '!AP90-'KB_CRITERIA AND CALCULATION '!AQ90)/Term) -> 0 | Y13: =IF(V3="Residential BTL", ""," formula (calculated automatically)") -> formula (calculated automatically) | BA13: Tier 3 | BB13: ='KB_CRITERIA AND CALCULATION '!AL114 | BE13: ='KB_CRITERIA AND CALCULATION '!AL117 | BH13: ='KB_CRITERIA AND CALCULATION '!AL120 | BJ13: ='KB_CRITERIA AND CALCULATION '!AL117
G14: =IF(OR(V3="Residential BTL",V3="Retention "), "","Monthly EBIDTA (please use EBITDA calculation tab)") -> Monthly EBIDTA (please use EBITDA calculation tab) | H14: =IF(H13="Yes",'EBITDA calc_'!K27/12,0) -> 0 | U14: Property Postcode | X14: Restricted countries: Afghanistan, Bosnia Herzegovina, Burundi, Central African Republic, Cuba, North Korea, Democratic Republic of the Congo, Eritrea, Ethiopia, Iran (Islamic Republic of), Iraq, Laos, Libyan Arab Jamahiriya, Myanmar, Pakistan, Somalia, South Sudan, Sudan, Syria, Uganda, Vanuatu, Venezuela, Yemen. | BA14: Tier 4 | BB14: ='KB_CRITERIA AND CALCULATION '!#REF! -> #REF! | BE14: ='KB_CRITERIA AND CALCULATION '!#REF! -> #REF! | BH14: ='KB_CRITERIA AND CALCULATION '!#REF! -> #REF! | BJ14: ='KB_CRITERIA AND CALCULATION '!#REF! -> #REF!
G15: Expat/ Foreign National? | H15: No | L15: =IF(AND(V2="Core",H15="Yes",H17="No"),"Note! Core Range, only Expat with UK Footprint + TI Jurisdictions allowed ","") | U15: Property Region | CV15: If red please remove so only the % or the £ is populated!
G16: Have ILR/Settled Status? | H16: No | U16: Borrower in a restricted country? | V16: No | AH16: ='KB_CRITERIA AND CALCULATION '!$L$2 -> Available Funding lines are: Zircon or Pearl
G17: Have a UK Footprint? | H17: No | U17: HMO? | V17: No | AH17: =TRIM('KB_CRITERIA AND CALCULATION '!$L$3) -> #N/A | AP17: 1
G18: Offshore Company/Trust? | H18: No | U18: MUFB? | V18: No | AP18: 2
G19: Qualifying Adverse Credit? | H19: No | U19: Flat above restricted* commercial? | V19: No | AI19: Pick an investor: | AP19: 3 | BB19: Basic | BE19: Fully R+D (Broker) | BH19: Fully R+D (Underwriter) | BJ19: Custom
G20: Missed Mortgage Payments | L20: ignore <=£350,telecom, utility | U20: Holiday/ Short term Let? | V20: No | AI20: ZBL | AO20: 4 | BA20: 0.04
G21: Unsecured Card/Loan Payments | U21: Development Exit? | V21: No | AY21: Net Loan | BA21: Tier 1 | BB21: =IFERROR('KB_CRITERIA AND CALCULATION '!AL94,"-") -> 0 | BE21: ='KB_CRITERIA AND CALCULATION '!AL97 -> 0 | BH21: ='KB_CRITERIA AND CALCULATION '!AL100 -> 0 | BJ21: ='KB_CRITERIA AND CALCULATION '!AL103 -> 0
G22: Qualifying CCJs & Defaults | U22: New Build? | V22: No | BA22: Tier 2 | BB22: ='KB_CRITERIA AND CALCULATION '!AL95 -> 0 | BE22: ='KB_CRITERIA AND CALCULATION '!AL98 -> 0 | BH22: ='KB_CRITERIA AND CALCULATION '!AL101 -> 0 | BJ22: ='KB_CRITERIA AND CALCULATION '!AL104 -> 0
G23: Bankruptcy/IVA/DRO | L23: For offsore Company select Corporate | U23: PBSA/Serviced Accommodation? | V23: No | BA23: Tier 3 | BB23: ='KB_CRITERIA AND CALCULATION '!AL96 | BE23: ='KB_CRITERIA AND CALCULATION '!AL99 | BH23: ='KB_CRITERIA AND CALCULATION '!AL102 | BJ23: ='KB_CRITERIA AND CALCULATION '!AL105
G24: Borrower Type | H24: Individual
G26: Initial Term (Months) | H26: =IF(V5="3 Year Fixed",36, IF(V5="5 Year Fixed",60,IF(V5="Tracker",24,24))) -> 24 | Q26: Tier Selected | R26: =Product_Selected -> 1) Standard | BA26: Tier 4 | BB26: ='KB_CRITERIA AND CALCULATION '!#REF! -> #REF! | BE26: ='KB_CRITERIA AND CALCULATION '!#REF! -> #REF! | BH26: ='KB_CRITERIA AND CALCULATION '!#REF! -> #REF! | BJ26: ='KB_CRITERIA AND CALCULATION '!#REF! -> #REF!
C27: Loan | G27: Customer Type | H27: New Customer | Q27: Product Type | S27: Rate | T27: Roll & Defer | U27: Net Loan | V27: GL | W27: Monthly DD | X27: Avg Annual Cost | Y27: MAX NL | Z27: MAX NL EXC TS | AA27: Comments
G28: Rates | H28: =IF(V5="Tracker","Tracker","Fixed") -> Fixed | Q28: Tracker Rate 2% fee | S28: =IF(OR(V3="Residential BTL",V3="Retention "),'KB Model Suggestions Tr 2yr'!J8,'KB_C&S Opt Roll Defer '!J8) -> 0.0899 | T28: ="R:"&IF(AND(OR(V3="Residential BTL",V3="Retention "),Roll2>9),9,IF(AND(OR(V3="Semi-Commercial",V3="Commercial"),Roll2>6),6,Roll2))&" D:"&TEXT(IF(AND(OR(V3="Residential BTL",V3="Retention "),Defer2>2%),2%,IF(AND(OR(V3="Semi-Commercial",V3="Commercial"),Defer2>1.5%),1.5%,Defer2)),"0.00%") -> R: D:0.00% | U28: =V28-(V28*(IF(Defer2>2%,2%,Defer2)/12)*24)-(V28*(S28-IF(Defer2>2%,2%,Defer2))/12*IF(Roll2>9,9,Roll2))-(V28*'KB Model Suggestions Tr 2yr'!S30) -> 0 | V28: =IF(OR(V3="Residential BTL",V3="Retention "), MIN(IF(($V$9*24)/((($S$28-BBR+'Product Data'!$K$2-IF(Defer2>2%,2%,Defer2))/12)*(24-IF(Roll2>9,9,Roll2))*'Product Data'!$P$18)> 'KB Model Suggestions Tr 2yr'!L8, 'KB Model Suggestions Tr 2yr'!L8,($V$9*24)/((($S$28-BBR+'Product Data'!$K$2-IF(Defer2>2%,2%,Defer2))/12)*(24-IF(Roll2>9,9,Roll2))*'Product Data'!$P$18)),'Product Data'!P16), IF(OR(V3<>"Residential BTL",V3<>"Retention "), MIN(IF((($V$9+$V$11)*24)/((($S$28-BBR+'Product Data'!$K$2-IF(Defer2>2%,2%,Defer2))/12)*(24-IF(Roll2>9,9,Roll2))*'Product Data'!$P$18)>'KB_C&S Opt Roll Defer '!L8,'KB_C&S Opt Roll Defer '!L8,(($V$9+$V$11)*24)/((($S$28-BBR+'Product Data'!$K$2-IF(Defer2>2%,2%,Defer2))/12)*(24-IF(Roll2>9,9,Roll2))*'Product Data'!$P$18)),'Product Data'!P16),0)) -> 0 | W28: =V28*(S28-(IF(Defer2>2%,2%,Defer2)))/12 -> 0 | X28: =((V28*(S28-IF(Defer2>2%,2%,Defer2))/12*(24-IF(Roll2>9,9,Roll2)))+V28*'KB Model Suggestions Tr 2yr'!S30)/2 -> 0 | Y28: =IF(OR(V3="Residential BTL",V3="Retention "),IF(OR(V28>='Product Data'!$P$16,'KB Model Suggestions Tr 2yr'!J10>='Product Data'!$P$16),'BTL Calculator'!U28,'KB Model Suggestions Tr 2yr'!J10),IF(OR(V28>='Product Data'!$P$16,'KB_C&S Opt Roll Defer '!N10>='Product Data'!$P$16),'BTL Calculator'!U28,'KB_C&S Opt Roll Defer '!N10)) -> 0 | Z28: =IF(OR(V3="Residential BTL",V3="Retention "),IF(AO28=1,(($V$9*24)/((($S$28-BBR+'Product Data'!$K$2-2%)/12)*(24-9)*'Product Data'!$P$18)-(($V$9*24)/((($S$28-BBR+'Product Data'!$K$2-2%)/12)*(24-9)*'Product Data'!$P$18)*2%/12)*24-(($V$9*24)/((($S$28-BBR+'Product Data'!$K$2-2%)/12)*(24-9)*'Product Data'!$P$18)*($S$28-2%)/12*9)-($V$9*24)/((($S$28-BBR+'Product Data'!$K$2-2%)/12)*(24-9)*'Product Data'!$P$18)*0.02),Y28),IF(AO28=1,((($V$9+$V$11)*24)/((($S$28-BBR+'Product Data'!$K$2-2%)/12)*(24-9)*'Product Data'!$P$18)-((($V$9+$V$11)*24)/((($S$28-BBR+'Product Data'!$K$2-2%)/12)*(24-9)*'Product Data'!$P$18)*2%/12)*24-((($V$9+$V$11)*24)/((($S$28-BBR+'Product Data'!$K$2-2%)/12)*(24-9)*'Product Data'!$P$18)*($S$28-2%)/12*9)-(($V$9+$V$11)*24)/((($S$28-BBR+'Product Data'!$K$2-2%)/12)*(24-9)*'Product Data'!$P$18)*0.02),Y28)) -> 0 | AA28: =IF(OR(V3="Residential BTL",V3="Retention "),IF(Y28="","Max Gross Loan achieved on this product, for higher loan size refer to Fusion.",'KB Model Suggestions Tr 2yr'!J3),IF(Y28="","Max Gross Loan achieved on this product, for higher loan size refer to Fusion.",'KB_C&S Opt Roll Defer '!J3)) -> Max LTV possible with 0m Rolled & 0.00% Deferred | AO28: =IF(ISNUMBER(SEARCH("need Top Slice",AA28)),1,"")
G29: Estimated Cheapest Tier | H29: =IF(OR(V3="Residential BTL",V3="Retention "),'KB_CRITERIA AND CALCULATION '!D36,'KB_CRITERIA AND CALCULATION '!W36) -> 1) Standard | Q29: Tracker Rate 4% fee | S29: =IF(OR(V3="Residential BTL",V3="Retention "),'KB Model Suggestions Tr 2yr'!F8,'KB_C&S Opt Roll Defer '!F8) -> 0.0804 | T29: ="R:"&IF(AND(OR(V3="Residential BTL",V3="Retention "),Roll4>9),9,IF(AND(OR(V3="Semi-Commercial",V3="Commercial"),Roll4>6),6,Roll4))&" D:"&TEXT(IF(AND(OR(V3="Residential BTL",V3="Retention "),Defer4>2%),2%,IF(AND(OR(V3="Semi-Commercial",V3="Commercial"),Defer4>1.5%),1.5%,Defer4)),"0.00%") -> R: D:0.00% | U29: =V29-(V29*(IF(Defer4>2%,2%,Defer4)/12)*24)-(V29*(S29-IF(Defer4>2%,2%,Defer4))/12*IF(Roll4>9,9,Roll4))-(V29*'KB Model Suggestions Tr 2yr'!T30) -> 0 | V29: =IF(OR(V3="Residential BTL",V3="Retention "),MIN(IF(($V$9*24)/(((S29-BBR+'Product Data'!$K$3-IF(Defer4>2%,2%,Defer4))/12)*(24-IF(Roll4>9,9,Roll4))*'Product Data'!$P$18)> 'KB Model Suggestions Tr 2yr'!H8,'KB Model Suggestions Tr 2yr'!H8,(V9*24)/(((S29-BBR+'Product Data'!$K$3-IF(Defer4>2%,2%,Defer4))/12)*(24-IF(Roll4>9,9,Roll4))*'Product Data'!$P$18)),'Product Data'!$P$16), IF(OR(V3<>"Residential BTL",V3<>"Retention "),MIN(IF((($V$9+V11)*24)/(((S29-BBR+'Product Data'!$K$3-IF(Defer4>2%,2%,Defer4))/12)*(24-IF(Roll4>9,9,Roll4))*'Product Data'!$P$18)>'KB_C&S Opt Roll Defer '!H8,'KB_C&S Opt Roll Defer '!H8,((V9+V11)*24)/(((S29-BBR+'Product Data'!$K$3-IF(Defer4>2%,2%,Defer4))/12)*(24-IF(Roll4>9,9,Roll4))*'Product Data'!$P$18)),'Product Data'!$P$16))) -> 0 | W29: =V29*(S29-(IF(Defer4>2%,2%,Defer4)))/12 -> 0 | X29: =((V29*(S29-IF(Defer4>2%,2%,Defer4))/12*(24-IF(Roll4>9,9,Roll4)))+V29*'KB Model Suggestions Tr 2yr'!T30)/2 -> 0 | Y29: =IF(OR(V3="Residential BTL",V3="Retention "),IF(OR(V29>='Product Data'!$P$16,'KB Model Suggestions Tr 2yr'!F10>='Product Data'!$P$16),'BTL Calculator'!U29,'KB Model Suggestions Tr 2yr'!F10),IF(OR(V29>='Product Data'!$P$16,'KB_C&S Opt Roll Defer '!N11>='Product Data'!$P$16),'BTL Calculator'!U29,'KB_C&S Opt Roll Defer '!N11)) -> 0 | Z29: =IF(OR(V3="Residential BTL",V3="Retention "),IF(AO29=1,($V$9*24)/((($S$29-BBR+'Product Data'!$K$3-2%)/12)*(24-9)*'Product Data'!$P$18)-(($V$9*24)/((($S$29-BBR+'Product Data'!$K$3-2%)/12)*(24-9)*'Product Data'!$P$18)*2%/12)*24-(($V$9*24)/((($S$29-BBR+'Product Data'!$K$3-2%)/12)*(24-9)*'Product Data'!$P$18)*($S$29-2%)/12*9)-($V$9*24)/((($S$29-BBR+'Product Data'!$K$3-2%)/12)*(24-9)*'Product Data'!$P$18)*0.04,Y29),IF(AO29=1,(($V$9+$V$11)*24)/((($S$29-BBR+'Product Data'!$K$3-2%)/12)*(24-9)*'Product Data'!$P$18)-((($V$9+$V$11)*24)/((($S$29-BBR+'Product Data'!$K$3-2%)/12)*(24-9)*'Product Data'!$P$18)*2%/12)*24-((($V$9+$V$11)*24)/((($S$29-BBR+'Product Data'!$K$3-2%)/12)*(24-9)*'Product Data'!$P$18)*($S$29-2%)/12*9)-(($V$9+$V$11)*24)/((($S$29-BBR+'Product Data'!$K$3-2%)/12)*(24-9)*'Product Data'!$P$18)*0.04,Y29)) -> 0 | AA29: =IF(OR(V3="Residential BTL",V3="Retention "),IF(Y29="","Max Gross Loan achieved on this product, for higher loan size refer to Fusion.",'KB Model Suggestions Tr 2yr'!F3),IF(Y29="","Max Gross Loan achieved on this product, for higher loan size refer to Fusion.",'KB_C&S Opt Roll Defer '!F3)) -> Max LTV possible with 0m Rolled & 0.00% Deferred | AO29: =IF(ISNUMBER(SEARCH("need Top Slice",AA29)),1,"")
