Workbook
Name _ftn1: DIP!#REF!
Name _ftn1: 'DIP Fusion'!$O$20
Name _ftn2: DIP!#REF!
Name _ftn2: 'DIP Fusion'!#REF!
Name _ftn3: DIP!#REF!
Name _ftn3: 'DIP Fusion'!$O$21
Name _Hlk83203796: DIP!$A$73
Name _Hlk83203796: 'DIP Fusion'!$A$87
Name _Hlk84245425: DIP!$A$56
Name _Hlk84245425: 'DIP Fusion'!$A$61
Name _Hlk98754409: DIP!$M$59
Name _Hlk98754409: 'DIP Fusion'!$M$63
Name Amber_P: #REF!
Name Application_Type: #REF!
Name Application_Type: #REF!
Name Application_Type: 'Input Sheet'!$C$12
Name APR: #REF!
Name APR: #REF!
Name Bank_Rate: 'EBITDA calc_'!#REF!
Name Bank_Rate: #REF!
Name BankBase: #REF!
Name BBR: #REF!
Name BBR: #REF!
Name BBR: #REF!
Name BBR: #REF!
Name BBR: 'Input Sheet'!$C$41
Name BBR_Override: #REF!
Name BBR_Override: #REF!
Name Core_Net_loan: #REF!
Name Core_Net_loan: #REF!
Name DD_In_Month1: #REF!
Name DD_In_Month1: #REF!
Name Defer_Term_Override: #REF!
Name Defer_Term_Override: #REF!
Name Defer2: #REF!
Name Defer2: #REF!
Name Defer4: #REF!
Name Defer4: #REF!
Name Defer6: #REF!
Name Defer6: #REF!
Name DeferedIntPercent: #REF!
Name DeferedIntPercent: #REF!
Name Deferred_Int_Owed: #REF!
Name Deferred_Int_Owed: #REF!
Name Deferred_Owed: #REF!
Name Deferred_Owed: #REF!
Name DIP_Selection: #REF!
Name DIP_Selection: #REF!
Name DIP_Selection: 'Input Sheet'!$P$2
Name EarthAve_P: #REF!
Name End_Date: #REF!
Name ERC_Rate: #REF!
Name Existing_Customer: #REF!
Name Existing_Customer: #REF!
Name Final_Month_DD_Req: #REF!
Name Final_Month_DD_Req: #REF!
Name Funder_Pic: INDIRECT(#REF!)
Name Funding_Line: #REF!
Name FusionP: 'Input Sheet'!$C$15
Name Future_Rent_TBL: #REF!

Sheet Main Calculations
XEV1: Yes | XEW1: No | XEX1: Please Choose
E3: Main Calculations
D7: Fusion | F7: Variable Bridge | H7: Fixed Bridge
D8: Specific Net Loan | E8: Normal Calc | F8: Specific Net Loan | G8: Normal Calc | H8: Specific Net Loan | I8: Normal Calc
C9: Gross Loan | D9: =CEILING(MIN(D36/(1-D13-(D30/12*24)-(D56*(D29-D41))),'Input Sheet'!$C$28,1000000000),1000) -> #VALUE! | F9: =CEILING(MIN((F36/(1-F13-(F30/12*24)-(F56*(F29-F41)))),F10),1000) -> #N/A | H9: =CEILING(MIN((H36/(1-H13-(H30/12*24)-(H56*(H29-H41)))),H10),1000) -> #N/A
C10: ='Input Sheet'!$B$27 -> Purchase Price | D10: ='Input Sheet'!$C$28 -> 0 | E10: ='Input Sheet'!$C$28 -> 0 | F10: ='Input Sheet'!$C$28 -> 0 | G10: ='Input Sheet'!$C$28 -> 0 | H10: ='Input Sheet'!$C$28 -> 0 | I10: ='Input Sheet'!$C$28 -> 0
C11: Rent (£ pm) | D11: ='Input Sheet'!$C$29 -> 0 | E11: ='Input Sheet'!$C$29 -> 0
C12: Top Slicing (£ pm) | D12: ='Input Sheet'!$C$31 -> 0 | E12: ='Input Sheet'!$C$31 -> 0
C13: Arrangement Fee (%) | D13: =IF('Input Sheet'!$C$34="",Rates!$E$37,'Input Sheet'!$C$34) -> 0.02 | E13: =IF('Input Sheet'!$C$34="",Rates!$E$37,'Input Sheet'!$C$34) -> 0.02 | F13: =IF('Input Sheet'!C34>0,'Input Sheet'!C34,CHOOSE(MATCH('Input Sheet'!I4,Rates!C7:J7,0),Rates!C13,Rates!D13,Rates!E13,Rates!G13,Rates!H13,Rates!I13,Rates!J13)) -> #N/A | G13: =IF('Input Sheet'!C34>0,'Input Sheet'!C34,CHOOSE(MATCH('Input Sheet'!I4,Rates!C7:J7,0),Rates!C13,Rates!D13,Rates!E13,Rates!G13,Rates!H13,Rates!I13,Rates!J13)) -> #N/A | H13: =IF('Input Sheet'!C34>0,'Input Sheet'!C34,CHOOSE(MATCH('Input Sheet'!I4,Rates!C21:J21,0),Rates!C27,Rates!D27,Rates!E27,Rates!G27,Rates!H27,Rates!I27,Rates!J27)) -> #N/A | I13: =IF('Input Sheet'!C34>0,'Input Sheet'!C34,CHOOSE(MATCH('Input Sheet'!I4,Rates!C21:J21,0),Rates!C27,Rates!D27,Rates!E27,Rates!G27,Rates!H27,Rates!I27,Rates!J27)) -> #N/A
C14: Broker Fee (%) | D14: ='Input Sheet'!$C$35 -> 0 | E14: ='Input Sheet'!$C$35 -> 0 | F14: ='Input Sheet'!$C$35 -> 0 | G14: ='Input Sheet'!$C$35 -> 0 | H14: ='Input Sheet'!$C$35 -> 0 | I14: ='Input Sheet'!$C$35 -> 0
C15: Additional Broker Fee (%) | D15: ='Input Sheet'!$C$36 -> 0 | E15: ='Input Sheet'!$C$36 -> 0 | F15: ='Input Sheet'!$C$36 -> 0 | G15: ='Input Sheet'!$C$36 -> 0 | H15: ='Input Sheet'!$C$36 -> 0 | I15: ='Input Sheet'!$C$36 -> 0
C16: Additional Broker Fee (£) | D16: ='Input Sheet'!$C$37 -> 0 | E16: ='Input Sheet'!$C$37 -> 0 | F16: ='Input Sheet'!$C$37 -> 0 | G16: ='Input Sheet'!$C$37 -> 0 | H16: ='Input Sheet'!$C$37 -> 0 | I16: ='Input Sheet'!$C$37 -> 0
C17: Exit Fee (%) Bridge Only | F17: ='Input Sheet'!$C$38 -> 0 | G17: ='Input Sheet'!$C$38 -> 0 | H17: ='Input Sheet'!$C$38 -> 0 | I17: ='Input Sheet'!$C$38 -> 0
C18: Commitment Fee (£) | D18: ='Input Sheet'!$C$39 -> 0 | E18: ='Input Sheet'!$C$39 -> 0 | F18: ='Input Sheet'!$C$39 -> 0 | G18: ='Input Sheet'!$C$39 -> 0 | H18: ='Input Sheet'!$C$39 -> 0 | I18: ='Input Sheet'!$C$39 -> 0
C19: 1st Charge Outstanding (£) | D19: ='Input Sheet'!$D$17 -> 0 | E19: ='Input Sheet'!$D$17 -> 0 | F19: ='Input Sheet'!$D$17 -> 0 | G19: ='Input Sheet'!$D$17 -> 0 | H19: ='Input Sheet'!$D$17 -> 0 | I19: ='Input Sheet'!$D$17 -> 0
C20: BBR | D20: ='Input Sheet'!$C$41 -> 0.04 | E20: ='Input Sheet'!$C$41 -> 0.04 | F20: ='Input Sheet'!$C$41 -> 0.04 | G20: ='Input Sheet'!$C$41 -> 0.04 | H20: ='Input Sheet'!$C$41 -> 0.04 | I20: ='Input Sheet'!$C$41 -> 0.04
C21: BBR (pm) % | D21: =$D$20/12 -> 0.0033333333 | E21: =$D$20/12 -> 0.0033333333 | F21: =$D$20/12 -> 0.0033333333 | G21: =$D$20/12 -> 0.0033333333 | H21: =$D$20/12 -> 0.0033333333 | I21: =$D$20/12 -> 0.0033333333
C22: BBR Cost £ | D22: =D20*D9*'Input Sheet'!$F$8/12 -> #VALUE! | E22: =E20*E32*'Input Sheet'!$F$8/12 -> 0 | F22: =F20*F9*'Input Sheet'!$I$8/12 -> #N/A | G22: =G20*G32*'Input Sheet'!$I$8/12 -> 0
C23: Product Type | D23: ='Input Sheet'!$C$13 -> 0 | E23: ='Input Sheet'!$C$13 -> 0 | F23: ='Input Sheet'!$C$13 -> 0 | G23: ='Input Sheet'!$C$13 -> 0 | H23: ='Input Sheet'!$C$13 -> 0 | I23: ='Input Sheet'!$C$13 -> 0
C24: Sub Product | D24: ='Input Sheet'!$F$5 | E24: ='Input Sheet'!$F$5 | F24: ='Input Sheet'!$C$14 -> 0 | G24: ='Input Sheet'!$C$14 -> 0 | H24: ='Input Sheet'!$C$14 -> 0 | I24: ='Input Sheet'!$C$14 -> 0
C25: Rate Override (Optional) | D25: {=IF('Input Sheet'!$F$6>0,'Input Sheet'!$F$6+BBR,"")} | E25: {=IF('Input Sheet'!$F$6>0,'Input Sheet'!$F$6+BBR,"")} | F25: ='Input Sheet'!I6 -> 0 | G25: ='Input Sheet'!I6 -> 0 | H25: ='Input Sheet'!L6 -> 0 | I25: ='Input Sheet'!L6 -> 0
C26: Coupon / Fixed rate % | D26: =IF($D$25<>"",$D$25, IF(AND('Input Sheet'!$C$15="Yes",'Input Sheet'!$C$13="Residential"),Rates!$E$42, IF($D$23="Residential", IF($D$9<=Rates!E36,Rates!E33, IF($D$9<=Rates!F36,Rates!F33, Rates!G33)), IF($D$23="Semi & Full Commercial", IF($D$9<=Rates!E36,Rates!E34, IF($D$9<=Rates!F36,Rates!F34, Rates!G34)), "")))) | E26: =IF($E$25<>"",$E$25, IF(AND('Input Sheet'!$C$15="Yes",'Input Sheet'!$C$13="Residential"),Rates!$E$42, IF($E$23="Residential", IF(E32<=Rates!E36,Rates!E33, IF(E32<=Rates!F36,Rates!F33, Rates!G33)), IF($E$23="Semi & Full Commercial", IF(E32<=Rates!E36,Rates!E34, IF(E32<=Rates!F36,Rates!F34, Rates!G34)), "")))) | F26: ='Input Sheet'!$I$5 | G26: ='Input Sheet'!$I$5 | H26: ='Input Sheet'!$L$5 | I26: ='Input Sheet'!$L$5
C27: Coupon / Fixed rate £ | D27: =D26*D9*'Input Sheet'!$F$8/12 -> #VALUE! | E27: =E26*E32*'Input Sheet'!$F$8/12 -> #VALUE! | F27: =F26*F9*'Input Sheet'!$I$8 -> #VALUE! | G27: =G26*G32*'Input Sheet'!$I$8 -> #VALUE!
C28: Rolled Months | D28: ='Input Sheet'!$F$7 -> 6 | E28: ='Input Sheet'!$F$7 -> 6 | F28: ='Input Sheet'!$I$7 -> 3 | G28: ='Input Sheet'!$I$7 -> 3 | H28: ='Input Sheet'!$L$7 -> 3 | I28: ='Input Sheet'!$L$7 -> 3
C29: Term | D29: ='Input Sheet'!$F$8 -> 24 | E29: ='Input Sheet'!$F$8 -> 24 | F29: ='Input Sheet'!$I$8 -> 12 | G29: ='Input Sheet'!$I$8 -> 12 | H29: ='Input Sheet'!$L$8 -> 12 | I29: ='Input Sheet'!$L$8 -> 12
C30: Deferred (%) | D30: ='Input Sheet'!$F$9 -> 0 | E30: ='Input Sheet'!$F$9 -> 0
C31: Full Annual / Monthly Rate (%) | D31: =IF($D$25="",D26+BBR,$D$25) -> #VALUE! | E31: =IF($E$25="",E26+BBR,$E$25) -> #VALUE! | F31: =(F26*12)+F20 -> #VALUE! | G31: =(G26*12)+G20 -> #VALUE! | H31: =H26*12 -> #VALUE! | I31: =I26*12 -> #VALUE!
C32: Gross Loan | E32: =IF('Input Sheet'!$C$11>'Input Sheet'!$C$28,'Input Sheet'!$C$28,'Input Sheet'!$C$11) -> 0 | G32: =IF('Input Sheet'!$C$11>'Input Sheet'!$C$28,'Input Sheet'!$C$28,'Input Sheet'!$C$11) -> 0 | I32: =IF('Input Sheet'!$C$11>'Input Sheet'!$C$28,'Input Sheet'!$C$28,'Input Sheet'!$C$11) -> 0
C33: Gross LTV | D33: =IFERROR((D9+D19)/D10,0) -> 0 | E33: =IFERROR((E32+E19)/E10,0) -> 0 | F33: =IFERROR((F9+F19)/F10,0) -> 0 | G33: =IFERROR((G32+G19)/G10,0) -> 0 | H33: =IFERROR((H9+H19)/H10,0) -> 0 | I33: =IFERROR((I32+I19)/I10,0) -> 0
C34: NPB | D34: =D35+D38 -> #VALUE! | E34: =E35+E38 -> #VALUE! | F34: =F35+F38 -> #N/A | G34: =G35+G38 -> #N/A | H34: =H35+H38 -> #N/A | I34: =I35+I38 -> #N/A
C35: Net Loan | D35: =D9-D44-D38-D43 -> #VALUE! | E35: =E32-E44-E38-E43 -> #VALUE! | F35: =F9-F38-F43 -> #N/A | G35: =G32-G38-G43 -> #N/A | H35: =H9-H38-H43 -> #N/A | I35: =I32-I38-I43 -> #N/A
C36: Specific Net Loan | D36: =IF('Input Sheet'!$D$15>'Input Sheet'!$C$28,'Input Sheet'!$C$28,'Input Sheet'!$D$15) -> 0 | F36: =IF('Input Sheet'!$D$15>'Input Sheet'!$C$28,'Input Sheet'!$C$28,'Input Sheet'!$D$15) -> 0 | H36: =IF('Input Sheet'!$D$15>'Input Sheet'!$C$28,'Input Sheet'!$C$28,'Input Sheet'!$D$15) -> 0
C37: Net LTV | D37: =IFERROR(D35/D10,0) -> 0 | E37: =IFERROR(E35/E10,0) -> 0 | F37: =IFERROR((F35+IF('Input Sheet'!$C$17="Yes",F19,0))/F10,0) -> 0 | G37: =IFERROR((G35+IF('Input Sheet'!$C$17="Yes",G19,0))/G10,0) -> 0 | H37: =IFERROR((H35+IF('Input Sheet'!$C$17="Yes",H19,0))/H10,0) -> 0 | I37: =IFERROR((I35+IF('Input Sheet'!$C$17="Yes",I19,0))/I10,0) -> 0
C38: Arrangement Fee (£) | D38: =D9*D13 -> #VALUE! | E38: =E32*E13 -> 0 | F38: =F9*F13 -> #N/A | G38: =G32*G13 -> #N/A | H38: =H9*H13 -> #N/A | I38: =I32*I13 -> #N/A
C39: Broker Fee (£) | D39: =D9*D14 -> #VALUE! | E39: =E32*E14 -> 0 | F39: =F9*F14 -> #N/A | G39: =G32*G14 -> 0 | H39: =H9*H14 -> #N/A | I39: =I32*I14 -> 0
C40: Additional Broker Fee (£) | D40: =IF('Input Sheet'!$C$37>0,'Input Sheet'!$C$37,D9*D15) -> #VALUE! | E40: =IF('Input Sheet'!$C$37>0,'Input Sheet'!$C$37,E32*E15) -> 0 | F40: =IF('Input Sheet'!$C$37>0,'Input Sheet'!$C$37,F9*F15) -> #N/A | G40: =IF('Input Sheet'!$C$37>0,'Input Sheet'!$C$37,G32*G15) -> 0 | H40: =IF('Input Sheet'!$C$37>0,'Input Sheet'!$C$37,H9*H15) -> #N/A | I40: =IF('Input Sheet'!$C$37>0,'Input Sheet'!$C$37,I32*I15) -> 0
C41: Serviced Months | D41: =IF(D29-D28<0,0,D29-D28) -> 18 | E41: =IF(E29-E28<0,0,E29-E28) -> 18 | F41: =IF(F29-F28<0,0,F29-F28) -> 9 | G41: =IF(G29-G28<0,0,G29-G28) -> 9 | H41: =IF(H29-H28<0,0,H29-H28) -> 9 | I41: =IF(I29-I28<0,0,I29-I28) -> 9
C42: Serviced Interest | D42: =D9*(D29-D28)*(D31-D30)/12 -> #VALUE! | E42: =E32*(E29-E28)*(E31-E30)/12 -> #VALUE! | F42: =F9*(F29-F28)*F31/12 -> #N/A | G42: =G32*(G29-G28)*G31/12 -> #VALUE! | H42: =H9*(H29-H28)*H31/12 -> #N/A | I42: =I32*(I29-I28)*I31/12 -> #VALUE!
C43: Rolled Interest (£) | D43: =D9*(D31-D30)*D28/12 -> #VALUE! | E43: =E32*(E31-E30)*E28/12 -> #VALUE! | F43: =F9*F56*F28 -> #N/A | G43: =G32*G31*G28/12 -> #VALUE! | H43: =H9*H56*H28 -> #N/A | I43: =I32*I31*I28/12 -> #VALUE!
C44: Deferred (£) | D44: =(D9*D30/12)*24 -> #VALUE! | E44: =(E32*E30/12)*24 -> 0
...

Sheet Input Sheet
E2: TRUE | G2: =IF(OR(C13="Mix Rate",C17="Yes"),FALSE,E2) -> TRUE | H2: TRUE | K2: TRUE | M2: =COUNTIF(G2:K2,TRUE) -> 3 | N2: Go to Indicatives | P2: {=_xlfn.IFS( AND(C15="Yes", E2=TRUE), "Fusion Premier", E2=TRUE, "Fusion", H2=TRUE, "Variable", K2=TRUE, "Fixed", TRUE, "None" )} -> Fusion | Q2: =IF(SUM((E2=TRUE) + (H2=TRUE) + (K2=TRUE))=0,3,SUM((E2=TRUE) + (H2=TRUE) + (K2=TRUE))) -> 3
E3: Fusion | H3: Variable Bridge | K3: Fixed Bridge | N3: Notes to the Underwriter
B4: Bridging Loan Calculator | C4: =IF(AND(D11<>"",C28>0,D11>C28),"Loan Amount is more than Property value", "") | E4: Product Type | F4: =IF(C13="","Please select product type",C13) -> Please select product type | H4: Sub Product Type | I4: =IF(AND($C$13="Mix Rate",$C$17="Yes"),"Mix Rate 2nd Charge",IF($C$17="Yes","2nd Charge",IF($C$13="Mix Rate","Mix Rate",IF($C$13="","Please select product type",IF(AND($C$13<>"",$C$14=""),"Please select sub product",IF(AND($C$17="No",$C$14=""),"",$C$14)))))) -> Please select product type | J4: =IF(I13="", "", IF(I13<=60%, INDEX(Rates!C8:J8, MATCH(I4, Rates!C7:J7, 0)), IF(I13<=70%, INDEX(Rates!C9:J9, MATCH(I4, Rates!C7:J7, 0)), IF(I13<=100%, INDEX(Rates!C10:J10, MATCH(I4, Rates!C7:J7, 0)), "Use Rate Override")))) -> #N/A | K4: Sub Product Type | L4: =IF(AND($C$13="Mix Rate",$C$17="Yes"),"Mix Rate 2nd Charge",IF($C$17="Yes","2nd Charge",IF($C$13="Mix Rate","Mix Rate",IF($C$13="","Please select product type",IF(AND($C$13<>"",$C$14=""),"Please select sub product",IF(AND($C$17="No",$C$14=""),"",$C$14)))))) -> Please select product type | M4: =IF(L13="", "", IF(L13<=60%, INDEX(Rates!C22:J22, MATCH(I4, Rates!C21:J21, 0)), IF(L13<=70%, INDEX(Rates!C23:J23, MATCH(I4, Rates!C21:J21, 0)), IF(L13<=100%, INDEX(Rates!C24:J24, MATCH(I4, Rates!C21:J21, 0)), "Use Rate Override")))) -> #N/A
B5: v.1 05 November 25 | E5: Sub Product | F5: =IF(C15="Yes","Premier",IF(C13="","", IF(F12<=Rates!E36,"Fusion S", IF(F12<=Rates!F36,"Fusion M", "Fusion L")))) | H5: Coupon Rate (%) | I5: =_xlfn.IFNA(IF(I6>0, I6, IF(C20="Yes", J5, J4)), "") | J5: =IF(I4="", "", IF(C22<=60%, INDEX(Rates!C8:J8, MATCH(I4, Rates!C7:J7, 0)), IF(C22<=70%, INDEX(Rates!C9:J9, MATCH(I4, Rates!C7:J7, 0)), IF(C22<=75%, INDEX(Rates!C10:J10, MATCH(I4, Rates!C7:J7, 0)), "Use Rate Override")))) -> #N/A | K5: Fixed Rate (%) | L5: =_xlfn.IFNA(IF(L6>0, L6, IF(C20="Yes", M5, M4)), "") | M5: =IF(L4="", "", IF(C23<=60%, INDEX(Rates!C22:J22, MATCH(I4, Rates!C21:J21, 0)), IF(C23<=70%, INDEX(Rates!C23:J23, MATCH(I4, Rates!C21:J21, 0)), IF(C23<=75%, INDEX(Rates!C24:J24, MATCH(I4, Rates!C21:J21, 0)), "Use Rate Override")))) -> #N/A | P5: Title Insurance
B6: Loan | E6: Rate Override (Optional) | H6: Rate Override (Optional) | K6: Rate Override (Optional) | N6: Please enter Mix Rate Manually | P6: Eligibility | Q6: =IF(AND(F12>3000000,I12>3000000,L12>3000000),"No",IF(AND(C17="Yes",I12>3000000,L12>3000000),"No",IF(C13<>"Residential","No",IF(AND(Q7<>"",Q8<>"No", Q8<>"No",Q8<>"",OR(Q7="Individual",AND(Q7="Corporate",Q9<>"No",Q9<>""))),"Yes",IF(OR(AND(Q7="Corporate",Q9="No"),AND(Q7="Corporate",Q9="")),"No",IF(Q8="No","No","No")))))) -> No | S6: Eligible nationalities Individual: UK national/passport holder of EEA country, Channel Islands, Switzerland, USA, Canada, Australia or New Zealand. Corporate: company, Trust and partnership incorporated in the UK, EEA, Channel Islands, Switzerland or the British Virgin Islands. UBO must meet the individual nationality criteria even if company incorporated in the permitted list.
B7: Reference | C7: HubSpot reference | E7: Rolled Months | F7: 6 | H7: Rolled Months | I7: 3 | K7: Rolled Months | L7: 3 | N7: Rolled Months exceed Total Term | P7: Applicant Type
B8: Borrower Name | C8: xxxxx | E8: Term | F8: 24 | H8: Term | I8: 12 | K8: Term | L8: 12 | P8: Eligible Nationalities
B9: Property Address | C9: xxxxx | E9: Deferred (%) | P9: Country Of Incorporation
B10: Loan Start Date
B11: Gross Loan | D11: =IF(C20="Yes","",IF(C11="","",C11)) | E11: Full Annual Rate (%) | F11: =IF(F5="","",IF($F$6>=0,IF(C20="Yes",'Main Calculations'!D31,'Main Calculations'!E31),$F$6)) | H11: Full Monthly Rate (%) | I11: =IFERROR(IF(I5="","",IF(C20="Yes",'Main Calculations'!F31/12,'Main Calculations'!G31/12)),"") | K11: Full Monthly Rate (%) | L11: =IFERROR(IF(L5="","",IF(F16="Yes",'Main Calculations'!H31/12,'Main Calculations'!I31/12)),"") | P11: Title Insurance Premium
B12: Applicant Type | E12: Gross Loan | F12: =IF(C13="Mix Rate",0,IF(C17="Yes",0,IF(C13="",0,IF(C20="Yes",IF('Main Calculations'!D9<0,0,'Main Calculations'!D9),IF(D11=0,0,IF('Main Calculations'!E32<0,0,'Main Calculations'!E32)))))) -> 0 | H12: Gross Loan | I12: =IF(I5="",0,IF($C$20="Yes",'Main Calculations'!F9,'Main Calculations'!G32)) -> 0 | K12: Gross Loan | L12: =IF(L5="",0,IF($C$20="Yes",'Main Calculations'!H9,'Main Calculations'!I32)) -> 0 | N12: =IF(OR(AND(F12<100000,F12>0),AND(I12>0,I12<100000),AND(L12>0,L12<100000)),"Less than minimum loan",IF(OR(I12>=50000000,L12>=50000000, F12>=65000000),"Maxmium Loan Achieved","")) | P12: Fusion | Q12: =IF(Q6<>"No",IF(OR(F12<=0,F12>3000000),"NA",IF(((F12*0.0013)+(F12*0.0013)*12%)<392,392,(F12*0.0013)+(F12*0.0013)*12%)),"")
B13: Product Type | E13: Gross LTV | F13: =IFERROR(IF($C$17="Yes",0,IF($C$20="Yes",'Main Calculations'!D33,'Main Calculations'!E33)),0) -> 0 | H13: Gross LTV | I13: =IFERROR(IF($C$20="Yes",'Main Calculations'!F33,'Main Calculations'!G33),0) -> 0 | K13: Gross LTV | L13: =IFERROR(IF($C$20="Yes",'Main Calculations'!H33,'Main Calculations'!I33),0) -> 0 | N13: Max LTV Achieved | P13: Variable Bridge | Q13: =IF(Q6<>"No",IF(OR(I12>3000000,I12<=0),"NA",IF(((I12*0.0013)+(I12*0.0013)*12%)<392,392,(I12*0.0013)+(I12*0.0013)*12%)),"")
B14: Sub Product Bridge only | E14: NPB | F14: =IFERROR(IF($C$20="Yes",'Main Calculations'!D34,'Main Calculations'!E34),0) -> 0 | H14: NPB | I14: =IFERROR(IF($C$20="Yes",'Main Calculations'!F34,'Main Calculations'!G34),0) -> 0 | K14: NPB | L14: =IFERROR(IF($C$20="Yes",'Main Calculations'!H34,'Main Calculations'!I34),0) -> 0 | P14: Fixed Bridge | Q14: =IF(Q6<>"No",IF(OR(L12<=0,L12>3000000),"NA",IF(((L12*0.0013)+(L12*0.0013)*12%)<392,392,(L12*0.0013)+(L12*0.0013)*12%)),"")
B15: Fusion Premier | C15: No | D15: =IF(C20="Yes",C21,0) -> 0 | E15: Net Loan | F15: =IFERROR(IF($C$20="Yes",'Main Calculations'!D35,'Main Calculations'!E35),0) -> 0 | H15: Net Loan | I15: =IFERROR(IF($C$20="Yes",'Main Calculations'!F35,'Main Calculations'!G35),0) -> 0 | K15: Net Loan | L15: =IFERROR(IF($C$20="Yes",'Main Calculations'!H35,'Main Calculations'!I35),0) -> 0
B16: Multi Property Loan ? | C16: No | E16: Net LTV | F16: =IFERROR(IF($C$20="Yes",'Main Calculations'!D37,'Main Calculations'!E37),0) -> 0 | H16: Net LTV | I16: =IFERROR(IF($C$20="Yes",'Main Calculations'!F37,'Main Calculations'!G37),0) -> 0 | K16: Net LTV | L16: =IFERROR(IF($C$20="Yes",'Main Calculations'!H37,'Main Calculations'!I37),0) -> 0
B17: 2nd Charge | C17: No | D17: =IF(C17="Yes",C19,0) -> 0
B18: 1st Charge | E18: Arrangement Fee (£) | F18: =IFERROR(IF($C$20="Yes",'Main Calculations'!D38,'Main Calculations'!E38),0) -> 0 | H18: Arrangement Fee (£) | I18: =IFERROR(IF($C$20="Yes",'Main Calculations'!F38,'Main Calculations'!G38),0) -> 0 | K18: Arrangement Fee (£) | L18: =IFERROR(IF($C$20="Yes",'Main Calculations'!H38,'Main Calculations'!I38),0) -> 0
B19: 1st Charge | C19: =IF($C$16="Yes",'Multi Property Deal'!$R$64,'Input Sheet'!$C$18) -> 0 | E19: Proc Fee (%) | F19: =IFERROR(IF($C$20="Yes",'Main Calculations'!D39,'Main Calculations'!E39),0) -> 0 | H19: Proc Fee (%) | I19: =IFERROR(IF($C$20="Yes",'Main Calculations'!F39,'Main Calculations'!G39),0) -> 0 | K19: Proc Fee (%) | L19: =IFERROR(IF($C$20="Yes",'Main Calculations'!H39,'Main Calculations'!I39),0) -> 0
B20: Specific Net Loan ? | C20: No | E20: Broker Client Fee (£) | F20: =IFERROR(IF($C$20="Yes",'Main Calculations'!D40,'Main Calculations'!E40),0) -> 0 | H20: Broker Client Fee (£) | I20: =IFERROR(IF($C$20="Yes",'Main Calculations'!F40,'Main Calculations'!G40),0) -> 0 | K20: Broker Client Fee (£) | L20: =IFERROR(IF($C$20="Yes",'Main Calculations'!H40,'Main Calculations'!I40),0) -> 0
B21: Specific Net Loan (£)
B22: LTV Rate Range Variable | C22: {=IFERROR(Rates!$S$15:$S$15,0)} -> 0 | E22: Serviced Months | F22: =IFERROR(IF($C$20="Yes",'Main Calculations'!D41,'Main Calculations'!E41),0) -> 18 | H22: Serviced Months | I22: =IFERROR(IF($C$20="Yes",'Main Calculations'!F41,'Main Calculations'!G41),0) -> 9 | K22: Serviced Months | L22: =IFERROR(IF($C$20="Yes",'Main Calculations'!H41,'Main Calculations'!I41),0) -> 9
B23: LTV Rate Range Fixed | C23: =IFERROR(Rates!$S$29,0) -> 0 | E23: Rolled Interest (£) | F23: =IFERROR(IF($C$20="Yes",'Main Calculations'!D43,'Main Calculations'!E43),0) -> 0 | H23: Rolled Interest (£) | I23: =IFERROR(IF($C$20="Yes",'Main Calculations'!F43,'Main Calculations'!G43),0) -> 0 | K23: Rolled Interest (£) | L23: =IFERROR(IF($C$20="Yes",'Main Calculations'!H43,'Main Calculations'!I43),0) -> 0
E24: Deferred (£) | F24: =IFERROR(IF($C$20="Yes",'Main Calculations'!D44,'Main Calculations'!E44),0) -> 0
B25: Property | E25: Total Interest (Defer + Rolled + Serviced) | F25: =IFERROR(IF($C$20="Yes",'Main Calculations'!D45,'Main Calculations'!E45),0) -> 0 | H25: Total Interest (Rolled + Serviced) | I25: =IFERROR(IF($C$20="Yes",'Main Calculations'!F45,'Main Calculations'!G45),0) -> 0 | K25: Total Interest (Rolled + Serviced) | L25: =IFERROR(IF($C$20="Yes",'Main Calculations'!H45,'Main Calculations'!I45),0) -> 0
B26: Lending off | C26: Purchase Price
B27: =C26 -> Purchase Price | E27: APRC (%) | F27: =IFERROR(IF($C$20="Yes",'Main Calculations'!D47,'Main Calculations'!E47),"") -> 0 | H27: APRC (%) | I27: =IFERROR(IF($C$20="Yes",'Main Calculations'!F47,'Main Calculations'!G47),0) -> 0 | K27: APRC (%) | L27: =IFERROR(IF($C$20="Yes",'Main Calculations'!H47,'Main Calculations'!I47),0) -> 0
B28: =C26 -> Purchase Price | C28: =IF(C16="Yes",'Multi Property Deal'!$M$64,IF(AND($C$13="Residential",'Input Sheet'!$C$15="Yes"),'Fusion Portfolio'!$M$4,'Input Sheet'!$C$27)) -> 0 | E28: APRC (% pm) | F28: =IFERROR(IF($C$20="Yes",'Main Calculations'!D48,'Main Calculations'!E48),"") -> 0 | H28: APRC (% pm) | I28: =IFERROR(IF($C$20="Yes",'Main Calculations'!F48,'Main Calculations'!G48),0) -> 0 | K28: APRC (% pm) | L28: =IFERROR(IF($C$20="Yes",'Main Calculations'!H48,'Main Calculations'!I48),0) -> 0
B29: Rent (£ pm) | C29: =IF($C$15="Yes",'Fusion Portfolio'!$N$4,'Input Sheet'!$C$30) -> 0 | E29: Monthly Payment | F29: =IFERROR(IF($C$20="Yes",'Main Calculations'!D49,'Main Calculations'!E49),0) -> 0 | H29: Monthly Payment | I29: =IFERROR(IF($C$20="Yes",'Main Calculations'!F49,'Main Calculations'!G49),0) -> 0 | K29: Monthly Payment | L29: =IFERROR(IF($C$20="Yes",'Main Calculations'!H49,'Main Calculations'!I49),0) -> 0
B30: Rent (£ pm) | E30: ERC (£) Yr1 | F30: =IFERROR(IF($C$20="Yes",'Main Calculations'!D50,'Main Calculations'!E50),0) -> 0 | H30: Exit Fee (£) | I30: =IFERROR(IF($C$20="Yes",'Main Calculations'!F50,'Main Calculations'!G50),0) -> 0 | K30: Exit Fee (£) | L30: =IFERROR(IF($C$20="Yes",'Main Calculations'!H50,'Main Calculations'!I50),0) -> 0
B31: Top Slicing (£ pm) | E31: ERC (£) Yr2 | F31: =IFERROR(IF($C$20="Yes",'Main Calculations'!D51,'Main Calculations'!E51),0) -> 0
B33: Fee | E33: Roll Int Coupon (£) | F33: =IFERROR(IF($C$20="Yes",'Main Calculations'!D52,'Main Calculations'!E52),0) -> 0 | H33: Roll Int Coupon (£) | I33: =IFERROR(IF($C$20="Yes",'Main Calculations'!F52,'Main Calculations'!G52),0) -> 0
B34: Arrangement Fee (%) | E34: Roll Int BBR (£) | F34: =IFERROR(IF($C$20="Yes",'Main Calculations'!D53,'Main Calculations'!E53),0) -> 0 | H34: Roll Int BBR (£) | I34: =IFERROR(IF($C$20="Yes",'Main Calculations'!F53,'Main Calculations'!G53),0) -> 0
B35: Proc Fee (%) | E35: Full Int Coupon (£) | F35: =IFERROR(IF($C$20="Yes",'Main Calculations'!D27,'Main Calculations'!E27),0) -> 0 | H35: Full Int Coupon (£) | I35: =IFERROR(IF($C$20="Yes",'Main Calculations'!F27,'Main Calculations'!G27),0) -> 0
B36: Broker Client Fee (%) | E36: Full Int BBR (£) | F36: =IFERROR(IF($C$20="Yes",'Main Calculations'!D22,'Main Calculations'!E22),0) -> 0 | H36: Full Int BBR (£) | I36: =IFERROR(IF($C$20="Yes",'Main Calculations'!F22,'Main Calculations'!G22),0) -> 0
B37: Broker Client Fee (£)
B38: Exit Fee (%) Bridge Only | E38: Full Rate (pm) | F38: =IFERROR(IF('Input Sheet'!$C$20="Yes",'Main Calculations'!D54,'Main Calculations'!E54),"")
B39: Commitment Fee (£) | E39: Full Coupon Rate (pm) | F39: =IFERROR((IF(F5="",0,IF(C20="Yes",'Main Calculations'!D55,'Main Calculations'!E55))),"") -> 0
E40: Pay Rate (pm) | F40: =IFERROR(IF(C20="Yes",'Main Calculations'!D56,'Main Calculations'!E56),"")
B41: BBR | C41: 0.04 | E41: ICR | F41: =IF(F12=0,"",IF(C20="Yes",'Main Calculations'!D57,'Main Calculations'!E57)) | H41: ICR Too Low Please Adjust Loan Amount
B42: BBR (pm) | C42: =C41/12 -> 0.0033333333
...

Sheet DIP Premier
B3: Decision in Principle – Premier Fusion Loan
B6: This offer is valid for 30 days and is subject to satisfactory valuation, due diligence, documentation, and Credit Committee approval. The below terms do not constitute a commitment to provide funding by the Lender nor representation that such funding will be made available.
B7: Loan Details
B9: Application ID | C9: ='Input Sheet'!$C$7 -> HubSpot reference
B10: Properties | C10: As listed in Schedule 1 – List of Properties | D10: Name from Input page
B11: Borrower | C11: ='Input Sheet'!$C$8 -> xxxxx
B12: Guarantor | D12: Manual input
B13: Obligors | D13: Manual input
B14: Lender | C14: =$G$14 -> 0 | F14: Funding Line
B15: Loan Manager | C15: Market Financial Solutions Limited
B16: Purpose | C16: [To refinance [Properties OR [details of Properties]/Acquisition of [Properties OR [details of Properties]] | D16: Manual input
B17: Term | C17: 24 months from the date of funding, unless extended for another 12 months (at Lender’s discretion)
B18: Gross Loan Amount | C18: ="£"& TEXT('Input Sheet'!$F$12,"#,##")&" based on an assumed MV of £"&TEXT('Input Sheet'!$C$28,"#,##") -> £ based on an assumed MV of £
B19: Net Loan Amount | C19: ="£"&TEXT('Input Sheet'!$F$15+'Input Sheet'!$F$20,"#,##")&" net loan including any Broker Client Fee" -> £ net loan including any Broker Client Fee | D19: Hide if blank
B20: Advance | C20: ="£"&TEXT('Input Sheet'!$F$15,"#,##")&" net amount advanced on day 1" -> £ net amount advanced on day 1
B21: Retained Interest | C21: =TEXT('Input Sheet'!$F$23,"£#,##")&" / "&TEXT('Input Sheet'!$F$7,"##")&" months" -> £ / 6 months | D21: Hide if blank
B22: Deferred Interest | C22: =TEXT('Input Sheet'!$F$24,"£#,##")&" / "&TEXT('Input Sheet'!$F$9,"#.##%")&" of the Gross Loan Amount" -> £ / .% of the Gross Loan Amount | D22: Hide if blank
B23: Interest Rate (variable) | C23: ="Margin "&('Input Sheet'!F11-'Input Sheet'!C41)*100&"% per annum plus the applicable Bank of England Base Rate (“BBR”), equal to a total interest rate of "&'Input Sheet'!F11*100&"% per annum Any changes to BBR will be reflected in interest charged from the first day of the next calendar month. " -> #VALUE!
B24: Interest Charging Basis | C24: =TEXT('Input Sheet'!$F$22,"#,##")&" months serviced "&TEXT('Input Sheet'!$F$7,"#,##")&" months retained "&TEXT('Input Sheet'!$F$9,"0.00%")&" deferred" -> 18 months serviced 6 months retained 0.00% deferred | F24: Interest Payment | G24: monthly
B25: Interest Payments | C25: =TEXT('Input Sheet'!$F$29,"£#,##")&" based on current BBR, payable "&G24&" commencing ON "& TEXT(G25,"dd-mmm-yyyy") -> £ based on current BBR, payable monthly commencing ON 28-May-2026 | D25: <-- Check | F25: Commencing date | G25: =EDATE(TODAY(), 'Input Sheet'!$F$7) -> 46170
B26: Default Interest Rate | C26: Interest Rate plus an additional 2.00% per month
B27: Minimum Interest Period | C27: 6 months from the date of drawdown of the Advance
B30: Fees
B33: Commitment Fee | C33: =IF('Input Sheet'!$C$39>0,TEXT('Input Sheet'!$C$39,"£#,##"),"£0 ")&$G$33 -> £0 is a reasonable estimate of costs for undertaking the process necessary to prepare the Loan for completion, payable on acceptance of this Decision in Principle and is refundable upon completion Note we reserve the right to retain the commitment fee should the loan fail to complete due to matters outside of our control | E33: Can be removed as per Ildiko | G33: is a reasonable estimate of costs for undertaking the process necessary to prepare the Loan for completion, payable on acceptance of this Decision in Principle and is refundable upon completion Note we reserve the right to retain the commitment fee should the loan fail to complete due to matters outside of our control
B34: Arrangement / Product Fee | C34: ="2.00% of the Gross Loan Amount payable upon the first drawdown date "&IF(G34>0, "or, if earlier, "&TEXT(G34,"dd-mmm-yyyy"),"") -> 2.00% of the Gross Loan Amount payable upon the first drawdown date or, if earlier, 01-Jan-2022 | D34: <-- Check | F34: Earlier Date | G34: 44562
B35: Broker’s Commission | C35: ="£"&TEXT('Input Sheet'!$F$19,"#,##")&" deducted from the Arrangement Fee and payable as commission to the Borrower’s broker" -> £ deducted from the Arrangement Fee and payable as commission to the Borrower’s broker
B36: Broker Client Fee | C36: ="£"&TEXT('Input Sheet'!$F$20,"#,##")&" deducted from the Net Loan Amount and payable as commission to the Borrower’s broker" -> £ deducted from the Net Loan Amount and payable as commission to the Borrower’s broker | D36: Hide if blank
B37: Valuation Fee | C37: =TEXT($G$37,"£#,##") & " plus VAT payable to us in advance of a valuation being instructed" -> £ plus VAT payable to us in advance of a valuation being instructed | D37: <-- Check | F37: Valuation Fee
B38: Legal Fees | C38: Lender’s legal fees payable by the Borrower with amount to be confirmed at a future date
B39: Title Insurance Fee | C39: =TEXT('Input Sheet'!$Q$12,"£#,##0.00")&" plus insurance premium tax, equating to 0.13% of the Gross Loan Amount, subject to a minimum amount of £350." -> plus insurance premium tax, equating to 0.13% of the Gross Loan Amount, subject to a minimum amount of £350.
B40: Early Repayment Charge (“ERC”) | C40: 1. Any time during the Minimum Interest Period: 3.0% of the amount repaid PLUS any interest that would have been payable on the amount repaid from the date of repayment up to and including the final day of the Minimum Interest Period. 2. Following the Minimum Interest Period and subject to the ERC Threshold: a. 3.0% of the amount repaid during the first 12 months of the Term; b. 1.5% of the amount repaid during months 13 to 21 of the Term; and c. no ERC thereafter.
B41: ERC Threshold | C41: Following the Minimum Interest Period until the month 21 of the Term, the Borrower can prepay an aggregate amount of up to 25% of the Gross Loan Amount without any charge.
B42: Tariff of Charges | C42: as available on our website at [LINK]. The Loan Manager reserves its right to change the Tariff of Charges from time to time at its own discretion. | D42: No link available
B45: Security & Covenants
B48: Debenture | C48: ="A first rank debenture with fixed and floating charges over all assets and undertakings of "&G48&" , including mortgages over the Properties" -> A first rank debenture with fixed and floating charges over all assets and undertakings of ABC, EFG , including mortgages over the Properties | D48: <-- Check | F48: Company Name | G48: ABC, EFG
B49: Share Charge | C49: ="A first charge over the shares in "&G48 -> A first charge over the shares in ABC, EFG | D49: <-- Check
B50: First Legal Charge | C50: A first ranking legal charge over the Properties. If(corporate,[which is covered by the Debenture]) | D50: <-- Manual Check
B51: Guarantee | C51: ="A personal/corporate guarantee from" &G51&" for the repayment of the Gross Loan Amount plus all interest, default interest and costs and expenses." -> A personal/corporate guarantee from for the repayment of the Gross Loan Amount plus all interest, default interest and costs and expenses. | D51: <-- Check | F51: Gaurantor Name
B52: Loan to Value (“LTV”) | C52: ="Aggregate of the loan plus all fees and interest as a percentage of MV not to exceed "&TEXT('Input Sheet'!$F$13,"#.##%")&". To be tested quarterly with a compliance certificate to be provided within 30 days of the relevant period" -> Aggregate of the loan plus all fees and interest as a percentage of MV not to exceed .%. To be tested quarterly with a compliance certificate to be provided within 30 days of the relevant period
B53: Interest Cover | C53: As at any date, passing rental as a percentage of finance cost at that date; calculation period - a period of three months or, if less, the period from the date of drawdown of Advance to the date as at which the relevant calculation is made; finance costs - the aggregate amount of interest paid or payable to the Lender during any calculation period in respect of which passing rental has been calculated; and passing rental means, as at any date, the passing rental income that was received on a regular periodical basis by the Borrower during the calculation period ending that date;
...

Sheet Indicative All 3
D3: Bridging Loans | F3: Summary of Terms - Indicative Illustration
D4: ='Input Sheet'!$C$8 -> xxxxx | F4: =IF('Input Sheet'!$C$16="Yes", "Multi-Property",'Input Sheet'!$C$9) -> xxxxx | H4: ='Input Sheet'!B7 -> Reference | I4: ='Input Sheet'!$C$7 -> HubSpot reference
D5: ='Input Sheet'!B27 &": "& TEXT('Input Sheet'!C28,"£#,#")&" "&" Monthly rent: "&TEXT(IF(OR('Input Sheet'!C29 ="", 'Input Sheet'!C29 =0),"N/A", 'Input Sheet'!C29),"£#,#") -> Purchase Price: £ Monthly rent: N/A
A7: Range | D7: Fusion | F7: Variable Bridge | H7: Fixed Bridge
A8: Product Name | D8: ='Input Sheet'!$F$4 & " "& 'Input Sheet'!$F$5 -> Please select product type | F8: =IF('Input Sheet'!$C$13="Mix Rate", "Mix Rate",'Input Sheet'!$I$4) -> Please select product type | H8: =IF('Input Sheet'!$C$13="Mix Rate", "Mix Rate",'Input Sheet'!$I$4) -> Please select product type
A9: Initial Rate | D9: =IF('Input Sheet'!$F$5="","",TEXT(('Input Sheet'!$F$11-BBR),"0.00%")&" + BBR (pa)") | F9: =IF('Input Sheet'!I5="","",TEXT('Input Sheet'!I5,"0.00%")&" + BBR (pm)") | H9: =IF('Input Sheet'!L5="","",TEXT('Input Sheet'!L11,"0.00%")&" (pm)")
A10: Pay Rate | D10: =IF('Input Sheet'!$F$5="","",TEXT(('Input Sheet'!$F$11-BBR-'Input Sheet'!$F$9),"0.00%")&" + BBR (pa)") | F10: =$F$9 | H10: =$H$9
A11: Gross Loan (repayable at redemption) | D11: =IFERROR(TEXT('Input Sheet'!F12,"£0,#"),0) & " @ "&TEXT('Input Sheet'!$F$13,"0%")&" LTV" -> £0 @ 0% LTV | F11: =IFERROR(TEXT('Input Sheet'!I12,"£0,#"),0)&" "&"@ "&TEXT('Input Sheet'!$I$13,"0%")&" LTV" -> £0 @ 0% LTV | H11: =IFERROR(TEXT('Input Sheet'!L12,"£0,#"),0) & " @ "&TEXT('Input Sheet'!$L$13,"0%")&" LTV" -> £0 @ 0% LTV
A12: Net Loan (day 1 advance) | D12: =TEXT('Input Sheet'!F15,"£0,#") & " " & "@ " & TEXT('Input Sheet'!F16,"0%") & " LTV" -> £0 @ 0% LTV | F12: =IFERROR(TEXT('Input Sheet'!I15,"£0,#"),0) & " " &IFERROR("@ " & TEXT('Input Sheet'!I16,"0%") & " LTV","") -> £0 @ 0% LTV | H12: =IFERROR(TEXT('Input Sheet'!L15,"£0,#"),0) & " @ " & TEXT('Input Sheet'!L16,"0%") & " LTV" -> £0 @ 0% LTV
A13: Arrangement Fee | D13: =IFERROR(TEXT('Input Sheet'!F18,"£0,#"),0) &" " &"(" & TEXT('Main Calculations'!$D$13,"0.00%") &")" -> £0 (2.00%) | F13: =IFERROR(TEXT('Input Sheet'!I18,"£0,#")&" "&"("&TEXT('Main Calculations'!$F$13,"0.00%")&")","") | H13: =IFERROR(TEXT('Input Sheet'!L18,"£0,#")& " (" & TEXT('Main Calculations'!$H$13,"0.00%") &")","")
A14: Total Loan Term | D14: 24 Months | F14: ='Input Sheet'!I8 & " Months" -> 12 Months | H14: ='Input Sheet'!L8 & " Months" -> 12 Months
A15: Rolled Months Interest | D15: =IFERROR(TEXT('Input Sheet'!F23,"£0,#"),0) & " " &"(" & 'Input Sheet'!F7 & " months"&")" -> £0 (6 months) | F15: =IFERROR(TEXT('Input Sheet'!I23,"£0,#"),0) & " " &"(" & 'Input Sheet'!I7 & IF('Input Sheet'!I7="", "0 months",IF('Input Sheet'!I7=1, " month", " months"))&")" -> £0 (3 months) | H15: =IFERROR(TEXT('Input Sheet'!L23,"£0,#"),0)& " (" & 'Input Sheet'!L7 & IF('Input Sheet'!L7="", "0 months",IF('Input Sheet'!L7 = 1, " month"," months"))&")" -> £0 (3 months)
A16: Monthly Payment | D16: =TEXT('Input Sheet'!F29,"£0,#") & " " &"from month " & 'Input Sheet'!F7+1 -> £0 from month 7 | F16: =TEXT(IF('Input Sheet'!$I$8='Input Sheet'!$I$7,"Fully Rolled",'Input Sheet'!I29), "£0,#")& " " & IF('Input Sheet'!$I$7>='Input Sheet'!$I$8, "","from month " & 'Input Sheet'!$I$7+1) -> £0 from month 4 | H16: =TEXT(IF('Input Sheet'!L8='Input Sheet'!L7,"Fully Rolled",'Input Sheet'!L29),"£0,#") &" " &IF('Input Sheet'!$L$7>='Input Sheet'!$L$8,"","from month " & 'Input Sheet'!$L$7+1) -> £0 from month 4
A17: Deferred Interest | D17: =IF('Input Sheet'!F24>0,TEXT('Input Sheet'!F24,"£0#,#") & " " &"("&TEXT('Input Sheet'!F9,"0.00%"&")"),"N/A") -> N/A | F17: N/A | H17: N/A
B18: Min Interest Period | D18: 6 Months | F18: 3 Months | H18: 3 Months
A19: ERC/Exit Fee | D19: ="3% in Yr1, 1.5% in Yr2" &" (25% capital repayment allowed from month 7, no ERC after 21 months)" -> 3% in Yr1, 1.5% in Yr2 (25% capital repayment allowed from month 7, no ERC after 21 months) | F19: =IF('Input Sheet'!$C$38<=0,"N/A",'Input Sheet'!$C$38) -> N/A | H19: =IF('Input Sheet'!$C$38<=0,"N/A",'Input Sheet'!$C$38) -> N/A
A20: Proc Fee | D20: =IFERROR(IF('Input Sheet'!$C$35="TBC", "TBC",'Input Sheet'!$F$19),0) -> 0 | F20: =IFERROR(IF('Input Sheet'!$C$35="TBC", "TBC",'Input Sheet'!$I$19),0) -> 0 | H20: =IFERROR(IF('Input Sheet'!$C$35="TBC", "TBC",'Input Sheet'!$L$19),0) -> 0
A21: Broker Client Fee (To be deducted from the net loan) | D21: =IFERROR('Input Sheet'!F20,0) -> 0 | F21: =IFERROR('Input Sheet'!I20,0) -> 0 | H21: =IFERROR('Input Sheet'!L20,0) -> 0
A23: Commitment Fee | D23: =IF('Input Sheet'!$C$39=0, "TBC by the Underwriter", 'Input Sheet'!$C$39) -> TBC by the Underwriter | F23: Payable when DIP signed, refundable on completion
A24: Valuation Fee | D24: TBC by the Underwriter | F24: Payable when DIP is signed
A25: Lender Legal Fee | D25: TBC by the Underwriter | F25: Excludes the borrower's own legal cost
B26: Title Insurance Premium | D26: ='Input Sheet'!$Q$12 | F26: ='Input Sheet'!$Q$13 | H26: ='Input Sheet'!$Q$14
D27: Please note: indicative only, subject to full underwrite, valuation, credit report and other supporting evidence. This Document is confidential to the intended recipient. If you are not the intended recipient, do not use, copy or disclose the information in any way or act in reliance on it, and notify the sender immediately, then delete it from your system. Market Financial Solutions Ltd accepts no liability (to the fullest extent permitted by law) for opinions, conclusions and other information in this message which do not relate to its official business. No contracts or official orders will be confirmed by means of this document.
B34: Property Address | G34: Property Value | H34: Our Charge | I34: Outstanding Charge | XFC34: <-- Hide if Fusion Premier
B35: =IF('Multi Property Deal'!$B$4="","",'Multi Property Deal'!$B$4) | G35: =IF('Multi Property Deal'!$M$4="","",'Multi Property Deal'!$M$4) | H35: =IF('Multi Property Deal'!$P$4="","",'Multi Property Deal'!$P$4) | I35: =IF(B35="","",IF(SUM('Multi Property Deal'!$R$4:$R$6)=0,0,SUM('Multi Property Deal'!$R$4:$R$6)))
B36: =IF('Multi Property Deal'!$B$7="","",'Multi Property Deal'!$B$7) | G36: =IF('Multi Property Deal'!$M$7="","",'Multi Property Deal'!$M$7) | H36: =IF('Multi Property Deal'!$P$7="","",'Multi Property Deal'!$P$7) | I36: =IF(B36="","",IF(SUM('Multi Property Deal'!$R$7:$R$9)=0,0,SUM('Multi Property Deal'!$R$7:$R$9)))
B37: =IF('Multi Property Deal'!$B$10="","",'Multi Property Deal'!$B$10) | G37: =IF('Multi Property Deal'!$M$10="","",'Multi Property Deal'!$M$10) | H37: =IF('Multi Property Deal'!$P$10="","",'Multi Property Deal'!$P$10) | I37: =IF(B37="","",IF(SUM('Multi Property Deal'!$R$10:$R$12)=0,0,SUM('Multi Property Deal'!$R$10:$R$12)))
B38: =IF('Multi Property Deal'!$B$13="","",'Multi Property Deal'!$B$13) | G38: =IF('Multi Property Deal'!$M$13="","",'Multi Property Deal'!$M$13) | H38: =IF('Multi Property Deal'!$P$13="","",'Multi Property Deal'!$P$13) | I38: =IF(B38="","",IF(SUM('Multi Property Deal'!$R$13:$R$15)=0,0,SUM('Multi Property Deal'!$R$13:$R$15)))
B39: =IF('Multi Property Deal'!$B$16="","",'Multi Property Deal'!$B$16) | G39: =IF('Multi Property Deal'!$M$16="","",'Multi Property Deal'!$M$16) | H39: =IF('Multi Property Deal'!$P$16="","",'Multi Property Deal'!$P$16) | I39: =IF(B39="","",IF(SUM('Multi Property Deal'!$R$16:$R$18)=0,0,SUM('Multi Property Deal'!$R$16:$R$18)))
B40: =IF('Multi Property Deal'!$B$19="","",'Multi Property Deal'!$B$19) | G40: =IF('Multi Property Deal'!$M$19="","",'Multi Property Deal'!$M$19) | H40: =IF('Multi Property Deal'!$P$19="","",'Multi Property Deal'!$P$19) | I40: =IF(B40="","",IF(SUM('Multi Property Deal'!$R$19:$R$21)=0,0,SUM('Multi Property Deal'!$R$19:$R$21)))
B41: =IF('Multi Property Deal'!$B$22="","",'Multi Property Deal'!$B$22) | G41: =IF('Multi Property Deal'!$M$22="","",'Multi Property Deal'!$M$22) | H41: =IF('Multi Property Deal'!$P$22="","",'Multi Property Deal'!$P$22) | I41: =IF(B41="","",IF(SUM('Multi Property Deal'!$R$22:$R$24)=0,0,SUM('Multi Property Deal'!$R$22:$R$24)))
B42: =IF('Multi Property Deal'!$B$25="","",'Multi Property Deal'!$B$25) | G42: =IF('Multi Property Deal'!$M$25="","",'Multi Property Deal'!$M$25) | H42: =IF('Multi Property Deal'!$P$25="","",'Multi Property Deal'!$P$25) | I42: =IF(B42="","",IF(SUM('Multi Property Deal'!$R$22:$R$24)=0,0,SUM('Multi Property Deal'!$R$22:$R$24)))
B43: =IF('Multi Property Deal'!$B$28="","",'Multi Property Deal'!$B$28) | G43: =IF('Multi Property Deal'!$M$28="","",'Multi Property Deal'!$M$28) | H43: =IF('Multi Property Deal'!$P$28="","",'Multi Property Deal'!$P$28) | I43: =IF(B43="","",IF(SUM('Multi Property Deal'!$R$28:$R$30)=0,0,SUM('Multi Property Deal'!$R$28:$R$30)))
B44: =IF('Multi Property Deal'!$B$31="","",'Multi Property Deal'!$B$31) | G44: =IF('Multi Property Deal'!$M$31="","",'Multi Property Deal'!$M$31) | H44: =IF('Multi Property Deal'!$P$31="","",'Multi Property Deal'!$P$31) | I44: =IF(B44="","",IF(SUM('Multi Property Deal'!$R$31:$R$33)=0,0,SUM('Multi Property Deal'!$R$31:$R$33)))
B45: =IF('Multi Property Deal'!$B$34="","",'Multi Property Deal'!$B$34) | G45: =IF('Multi Property Deal'!$M$34="","",'Multi Property Deal'!$M$34) | H45: =IF('Multi Property Deal'!$P$34="","",'Multi Property Deal'!$P$34) | I45: =IF(B45="","",IF(SUM('Multi Property Deal'!$R$34:$R$36)=0,0,SUM('Multi Property Deal'!$R$34:$R$36)))

Sheet Indicative 2 only
D3: Bridging Loans | F3: Summary of Terms - Indicative Illustration
D4: ='Input Sheet'!$C$8 -> xxxxx | F4: =IF('Input Sheet'!$C$16="Yes", "Multi-Property",'Input Sheet'!$C$9) -> xxxxx | H4: ='Input Sheet'!B7 -> Reference | I4: ='Input Sheet'!$C$7 -> HubSpot reference
B5: =IF(AND(D7="Variable Bridge",G7="Fixed Bridge"),1,0) -> 0 | D5: ='Input Sheet'!B27 &": "& TEXT('Input Sheet'!C28,"£#,#")&" "&" Monthly rent: "&TEXT(IF(OR('Input Sheet'!C29 ="", 'Input Sheet'!C29 =0),"N/A", 'Input Sheet'!C29),"£#,#") -> Purchase Price: £ Monthly rent: N/A
A7: Range | D7: =IF('Input Sheet'!$G$2=TRUE,'Indicative All 3'!D7,'Indicative All 3'!F7) -> Fusion | G7: =IF('Input Sheet'!$K$2=TRUE,'Indicative All 3'!H7,'Indicative All 3'!F7) -> Fixed Bridge
A8: Product Name | D8: =IF($D$7="Fusion",'Indicative All 3'!D8,'Indicative All 3'!F8) -> Please select product type | G8: =IF('Input Sheet'!$K$2=TRUE,'Indicative All 3'!H8,'Indicative All 3'!F8) -> Please select product type
A9: Initial Rate | D9: =IF($D$7="Fusion",'Indicative All 3'!D9,'Indicative All 3'!F9) | G9: =IF('Input Sheet'!$K$2=TRUE,'Indicative All 3'!H9,'Indicative All 3'!F9)
A10: Pay Rate | D10: =IF($D$7="Fusion",'Indicative All 3'!D10,'Indicative All 3'!F10) | G10: =IF('Input Sheet'!$K$2=TRUE,'Indicative All 3'!H10,'Indicative All 3'!F10)
A11: Gross Loan (repayable at redemption) | D11: =IF($D$7="Fusion",'Indicative All 3'!D11,'Indicative All 3'!F11) -> £0 @ 0% LTV | G11: =IF('Input Sheet'!$K$2=TRUE,'Indicative All 3'!H11,'Indicative All 3'!F11) -> £0 @ 0% LTV
A12: Net Loan (day 1 advance) | D12: =IF($D$7="Fusion",'Indicative All 3'!D12,'Indicative All 3'!F12) -> £0 @ 0% LTV | G12: =IF('Input Sheet'!$K$2=TRUE,'Indicative All 3'!H12,'Indicative All 3'!F12) -> £0 @ 0% LTV
A13: Arrangement Fee | D13: =IF($D$7="Fusion",'Indicative All 3'!D13,'Indicative All 3'!F13) -> £0 (2.00%) | G13: =IF('Input Sheet'!$K$2=TRUE,'Indicative All 3'!H13,'Indicative All 3'!F13)
A14: Total Loan Term | D14: =IF($D$7="Fusion",'Indicative All 3'!D14,'Indicative All 3'!F14) -> 24 Months | G14: =IF('Input Sheet'!$K$2=TRUE,'Indicative All 3'!H14,'Indicative All 3'!F14) -> 12 Months
A15: Rolled Months Interest | D15: =IF($D$7="Fusion",'Indicative All 3'!D15,'Indicative All 3'!F15) -> £0 (6 months) | G15: =IF('Input Sheet'!$K$2=TRUE,'Indicative All 3'!H15,'Indicative All 3'!F15) -> £0 (3 months)
A16: Monthly Payment | D16: =IF($D$7="Fusion",'Indicative All 3'!D16,'Indicative All 3'!F16) -> £0 from month 7 | G16: =IF('Input Sheet'!$K$2=TRUE,'Indicative All 3'!H16,'Indicative All 3'!F16) -> £0 from month 4
B17: Deferred Interest | D17: =IF($D$7="Fusion",'Indicative All 3'!D17,'Indicative All 3'!F17) -> N/A | G17: =IF('Input Sheet'!$K$2=TRUE,'Indicative All 3'!H17,'Indicative All 3'!F17) -> N/A
B18: Min Interest Period | D18: =IF($D$7="Fusion",'Indicative All 3'!D18,'Indicative All 3'!F18) -> 6 Months | G18: =IF('Input Sheet'!$K$2=TRUE,'Indicative All 3'!H18,'Indicative All 3'!F18) -> 3 Months
A19: ERC/Exit Fee | D19: =IF($D$7="Fusion",'Indicative All 3'!D19,'Indicative All 3'!F19) -> 3% in Yr1, 1.5% in Yr2 (25% capital repayment allowed from month 7, no ERC after 21 months) | G19: =IF('Input Sheet'!$K$2=TRUE,'Indicative All 3'!H19,'Indicative All 3'!F19) -> N/A
A20: Proc Fee | D20: =IF($D$7="Fusion",'Indicative All 3'!D20,'Indicative All 3'!F20) -> 0 | G20: =IF('Input Sheet'!$K$2=TRUE,'Indicative All 3'!H20,'Indicative All 3'!F20) -> 0
A21: Broker Client Fee (To be deducted from the net loan) | D21: =IF($D$7="Fusion",'Indicative All 3'!D21,'Indicative All 3'!F21) -> 0 | G21: =IF('Input Sheet'!$K$2=TRUE,'Indicative All 3'!H21,'Indicative All 3'!F21) -> 0
A23: Commitment Fee | D23: =IF('Input Sheet'!$C$39=0, "TBC by the Underwriter", 'Input Sheet'!$C$39) -> TBC by the Underwriter | F23: Payable when DIP signed, refundable on completion
A24: Valuation Fee | D24: TBC by the Underwriter | F24: Payable when DIP is signed
A25: Lender Legal Fee | D25: TBC by the Underwriter | F25: Excludes the borrower's own legal cost
B26: Title Insurance Premium | D26: =IF($D$7="Fusion",'Indicative All 3'!D26,'Indicative All 3'!F26) | G26: =IF('Input Sheet'!$K$2=TRUE,'Indicative All 3'!H26,'Indicative All 3'!F26)
D27: Please note: indicative only, subject to full underwrite, valuation, credit report and other supporting evidence. This Document is confidential to the intended recipient. If you are not the intended recipient, do not use, copy or disclose the information in any way or act in reliance on it, and notify the sender immediately, then delete it from your system. Market Financial Solutions Ltd accepts no liability (to the fullest extent permitted by law) for opinions, conclusions and other information in this message which do not relate to its official business. No contracts or official orders will be confirmed by means of this document.
B35: Property Address | G35: Property Value | H35: Our Charge | I35: Outstanding Charge | XFC35: <-- Hide if Fusion Premier
B36: =IF('Multi Property Deal'!$B$4="","",'Multi Property Deal'!$B$4) | G36: =IF('Multi Property Deal'!$M$4="","",'Multi Property Deal'!$M$4) | H36: =IF('Multi Property Deal'!$P$4="","",'Multi Property Deal'!$P$4) | I36: =IF(B36="","",IF(SUM('Multi Property Deal'!$R$4:$R$6)=0,0,SUM('Multi Property Deal'!$R$4:$R$6)))
B37: =IF('Multi Property Deal'!$B$7="","",'Multi Property Deal'!$B$7) | G37: =IF('Multi Property Deal'!$M$7="","",'Multi Property Deal'!$M$7) | H37: =IF('Multi Property Deal'!$P$7="","",'Multi Property Deal'!$P$7) | I37: =IF(B37="","",IF(SUM('Multi Property Deal'!$R$7:$R$9)=0,0,SUM('Multi Property Deal'!$R$7:$R$9)))
B38: =IF('Multi Property Deal'!$B$10="","",'Multi Property Deal'!$B$10) | G38: =IF('Multi Property Deal'!$M$10="","",'Multi Property Deal'!$M$10) | H38: =IF('Multi Property Deal'!$P$10="","",'Multi Property Deal'!$P$10) | I38: =IF(B38="","",IF(SUM('Multi Property Deal'!$R$10:$R$12)=0,0,SUM('Multi Property Deal'!$R$10:$R$12)))
B39: =IF('Multi Property Deal'!$B$13="","",'Multi Property Deal'!$B$13) | G39: =IF('Multi Property Deal'!$M$13="","",'Multi Property Deal'!$M$13) | H39: =IF('Multi Property Deal'!$P$13="","",'Multi Property Deal'!$P$13) | I39: =IF(B39="","",IF(SUM('Multi Property Deal'!$R$13:$R$15)=0,0,SUM('Multi Property Deal'!$R$13:$R$15)))
B40: =IF('Multi Property Deal'!$B$16="","",'Multi Property Deal'!$B$16) | G40: =IF('Multi Property Deal'!$M$16="","",'Multi Property Deal'!$M$16) | H40: =IF('Multi Property Deal'!$P$16="","",'Multi Property Deal'!$P$16) | I40: =IF(B40="","",IF(SUM('Multi Property Deal'!$R$16:$R$18)=0,0,SUM('Multi Property Deal'!$R$16:$R$18)))
B41: =IF('Multi Property Deal'!$B$19="","",'Multi Property Deal'!$B$19) | G41: =IF('Multi Property Deal'!$M$19="","",'Multi Property Deal'!$M$19) | H41: =IF('Multi Property Deal'!$P$19="","",'Multi Property Deal'!$P$19) | I41: =IF(B41="","",IF(SUM('Multi Property Deal'!$R$19:$R$21)=0,0,SUM('Multi Property Deal'!$R$19:$R$21)))
B42: =IF('Multi Property Deal'!$B$22="","",'Multi Property Deal'!$B$22) | G42: =IF('Multi Property Deal'!$M$22="","",'Multi Property Deal'!$M$22) | H42: =IF('Multi Property Deal'!$P$22="","",'Multi Property Deal'!$P$22) | I42: =IF(B42="","",IF(SUM('Multi Property Deal'!$R$22:$R$24)=0,0,SUM('Multi Property Deal'!$R$22:$R$24)))
B43: =IF('Multi Property Deal'!$B$25="","",'Multi Property Deal'!$B$25) | G43: =IF('Multi Property Deal'!$M$25="","",'Multi Property Deal'!$M$25) | H43: =IF('Multi Property Deal'!$P$25="","",'Multi Property Deal'!$P$25) | I43: =IF(B43="","",IF(SUM('Multi Property Deal'!$R$22:$R$24)=0,0,SUM('Multi Property Deal'!$R$22:$R$24)))
B44: =IF('Multi Property Deal'!$B$28="","",'Multi Property Deal'!$B$28) | G44: =IF('Multi Property Deal'!$M$28="","",'Multi Property Deal'!$M$28) | H44: =IF('Multi Property Deal'!$P$28="","",'Multi Property Deal'!$P$28) | I44: =IF(B44="","",IF(SUM('Multi Property Deal'!$R$28:$R$30)=0,0,SUM('Multi Property Deal'!$R$28:$R$30)))
B45: =IF('Multi Property Deal'!$B$31="","",'Multi Property Deal'!$B$31) | G45: =IF('Multi Property Deal'!$M$31="","",'Multi Property Deal'!$M$31) | H45: =IF('Multi Property Deal'!$P$31="","",'Multi Property Deal'!$P$31) | I45: =IF(B45="","",IF(SUM('Multi Property Deal'!$R$31:$R$33)=0,0,SUM('Multi Property Deal'!$R$31:$R$33)))
B46: =IF('Multi Property Deal'!$B$34="","",'Multi Property Deal'!$B$34) | G46: =IF('Multi Property Deal'!$M$34="","",'Multi Property Deal'!$M$34) | H46: =IF('Multi Property Deal'!$P$34="","",'Multi Property Deal'!$P$34) | I46: =IF(B46="","",IF(SUM('Multi Property Deal'!$R$34:$R$36)=0,0,SUM('Multi Property Deal'!$R$34:$R$36)))

Sheet Single Indicative
D3: Bridging Loans | F3: Summary of Terms - Indicative Illustration
D4: ='Input Sheet'!$C$8 -> xxxxx | F4: =IF('Input Sheet'!$C$16="Yes", "Multi-Property",'Input Sheet'!$C$9) -> xxxxx | H4: ='Input Sheet'!B7 -> Reference | I4: ='Input Sheet'!$C$7 -> HubSpot reference
B5: =IF(D7<>"Fusion",1,0) -> 0 | D5: ='Input Sheet'!B27 &": "& TEXT('Input Sheet'!C28,"£#,#")&" "&" Monthly rent: "&TEXT(IF(OR('Input Sheet'!C29 ="", 'Input Sheet'!C29 =0),"N/A", 'Input Sheet'!C29),"£#,#") -> Purchase Price: £ Monthly rent: N/A
A7: Range | D7: =IF('Input Sheet'!$G$2=TRUE,'Indicative All 3'!D7,IF('Input Sheet'!$H$2=TRUE,'Indicative All 3'!F7,IF('Input Sheet'!$K$2=TRUE,'Indicative All 3'!H7))) -> Fusion
A8: Product Name | D8: =IF($D$7="Fusion",'Indicative All 3'!D8,IF('Input Sheet'!$H$2=TRUE,'Indicative All 3'!F8,IF('Input Sheet'!$K$2=TRUE,'Indicative All 3'!H8))) -> Please select product type
A9: Initial Rate | D9: =IF($D$7="Fusion",'Indicative All 3'!D9,IF('Input Sheet'!$H$2=TRUE,'Indicative All 3'!F9,IF('Input Sheet'!$K$2=TRUE,'Indicative All 3'!H9)))
A10: Pay Rate | D10: =IF('Input Sheet'!$E$2=TRUE,'Indicative All 3'!D10,IF('Input Sheet'!$H$2=TRUE,'Indicative All 3'!F10,IF('Input Sheet'!$K$2=TRUE,'Indicative All 3'!H10)))
A11: Gross Loan (repayable at redemption) | D11: =IF($D$7="Fusion",'Indicative All 3'!D11,IF('Input Sheet'!$H$2=TRUE,'Indicative All 3'!F11,IF('Input Sheet'!$K$2=TRUE,'Indicative All 3'!H11))) -> £0 @ 0% LTV
A12: Net Loan (day 1 advance) | D12: =IF($D$7="Fusion",'Indicative All 3'!D12,IF('Input Sheet'!$H$2=TRUE,'Indicative All 3'!F12,IF('Input Sheet'!$K$2=TRUE,'Indicative All 3'!H12))) -> £0 @ 0% LTV
A13: Arrangement Fee | D13: =IF($D$7="Fusion",'Indicative All 3'!D13,IF('Input Sheet'!$H$2=TRUE,'Indicative All 3'!F13,IF('Input Sheet'!$K$2=TRUE,'Indicative All 3'!H13))) -> £0 (2.00%)
A14: Total Loan Term | D14: =IF($D$7="Fusion",'Indicative All 3'!D14,IF('Input Sheet'!$H$2=TRUE,'Indicative All 3'!F14,IF('Input Sheet'!$K$2=TRUE,'Indicative All 3'!H14))) -> 24 Months
A15: Rolled Months Interest | D15: =IF($D$7="Fusion",'Indicative All 3'!D15,IF('Input Sheet'!$H$2=TRUE,'Indicative All 3'!F15,IF('Input Sheet'!$K$2=TRUE,'Indicative All 3'!H15))) -> £0 (6 months)
A16: Monthly Payment | D16: =IF($D$7="Fusion",'Indicative All 3'!D16,IF('Input Sheet'!$H$2=TRUE,'Indicative All 3'!F16,IF('Input Sheet'!$K$2=TRUE,'Indicative All 3'!H16))) -> £0 from month 7
B17: Deferred Interest | D17: =IF('Input Sheet'!$E$2=TRUE,'Indicative All 3'!D17,IF('Input Sheet'!$H$2=TRUE,'Indicative All 3'!F17,IF('Input Sheet'!$K$2=TRUE,'Indicative All 3'!H17))) -> N/A
B18: Min Interest Period | D18: =IF($D$7="Fusion",'Indicative All 3'!D18,IF('Input Sheet'!$H$2=TRUE,'Indicative All 3'!F18,IF('Input Sheet'!$K$2=TRUE,'Indicative All 3'!H18))) -> 6 Months
A19: ERC/Exit Fee | D19: =IF($D$7="Fusion",'Indicative All 3'!D19,IF('Input Sheet'!$H$2=TRUE,'Indicative All 3'!F19,IF('Input Sheet'!$K$2=TRUE,'Indicative All 3'!H19))) -> 3% in Yr1, 1.5% in Yr2 (25% capital repayment allowed from month 7, no ERC after 21 months)
A20: Proc Fee | D20: =IF($D$7="Fusion",'Indicative All 3'!D20,IF('Input Sheet'!$H$2=TRUE,'Indicative All 3'!F20,IF('Input Sheet'!$K$2=TRUE,'Indicative All 3'!H20))) -> 0
A21: Broker Client Fee (To be deducted from the net loan) | D21: =IF($D$7="Fusion",'Indicative All 3'!D21,IF('Input Sheet'!$H$2=TRUE,'Indicative All 3'!F21,IF('Input Sheet'!$K$2=TRUE,'Indicative All 3'!H21))) -> 0
A23: Commitment Fee | D23: =IF('Input Sheet'!$C$39=0, "TBC by the Underwriter", 'Input Sheet'!$C$39) -> TBC by the Underwriter | F23: Payable when DIP signed, refundable on completion
A24: Valuation Fee | D24: TBC by the Underwriter | F24: Payable when DIP is signed
A25: Lender Legal Fee | D25: TBC by the Underwriter | F25: Excludes the borrower's own legal cost
B26: Title Insurance Premium | D26: =IF($D$7="Fusion",'Indicative All 3'!D26,IF('Input Sheet'!$H$2=TRUE,'Indicative All 3'!F26,IF('Input Sheet'!$K$2=TRUE,'Indicative All 3'!H26)))
D27: Please note: indicative only, subject to full underwrite, valuation, credit report and other supporting evidence. This Document is confidential to the intended recipient. If you are not the intended recipient, do not use, copy or disclose the information in any way or act in reliance on it, and notify the sender immediately, then delete it from your system. Market Financial Solutions Ltd accepts no liability (to the fullest extent permitted by law) for opinions, conclusions and other information in this message which do not relate to its official business. No contracts or official orders will be confirmed by means of this document.
B35: Property Address | G35: Property Value | H35: Our Charge | I35: Outstanding Charge | L35: <-- Hide if Fusion Premier
B36: =IF('Multi Property Deal'!$B$4="","",'Multi Property Deal'!$B$4) | G36: =IF('Multi Property Deal'!$M$4="","",'Multi Property Deal'!$M$4) | H36: =IF('Multi Property Deal'!$P$4="","",'Multi Property Deal'!$P$4) | I36: =IF(B36="","",IF(SUM('Multi Property Deal'!$R$4:$R$6)=0,0,SUM('Multi Property Deal'!$R$4:$R$6)))
B37: =IF('Multi Property Deal'!$B$7="","",'Multi Property Deal'!$B$7) | G37: =IF('Multi Property Deal'!$M$7="","",'Multi Property Deal'!$M$7) | H37: =IF('Multi Property Deal'!$P$7="","",'Multi Property Deal'!$P$7) | I37: =IF(B37="","",IF(SUM('Multi Property Deal'!$R$7:$R$9)=0,0,SUM('Multi Property Deal'!$R$7:$R$9)))
B38: =IF('Multi Property Deal'!$B$10="","",'Multi Property Deal'!$B$10) | G38: =IF('Multi Property Deal'!$M$10="","",'Multi Property Deal'!$M$10) | H38: =IF('Multi Property Deal'!$P$10="","",'Multi Property Deal'!$P$10) | I38: =IF(B38="","",IF(SUM('Multi Property Deal'!$R$10:$R$12)=0,0,SUM('Multi Property Deal'!$R$10:$R$12)))
B39: =IF('Multi Property Deal'!$B$13="","",'Multi Property Deal'!$B$13) | G39: =IF('Multi Property Deal'!$M$13="","",'Multi Property Deal'!$M$13) | H39: =IF('Multi Property Deal'!$P$13="","",'Multi Property Deal'!$P$13) | I39: =IF(B39="","",IF(SUM('Multi Property Deal'!$R$13:$R$15)=0,0,SUM('Multi Property Deal'!$R$13:$R$15)))
B40: =IF('Multi Property Deal'!$B$16="","",'Multi Property Deal'!$B$16) | G40: =IF('Multi Property Deal'!$M$16="","",'Multi Property Deal'!$M$16) | H40: =IF('Multi Property Deal'!$P$16="","",'Multi Property Deal'!$P$16) | I40: =IF(B40="","",IF(SUM('Multi Property Deal'!$R$16:$R$18)=0,0,SUM('Multi Property Deal'!$R$16:$R$18)))
B41: =IF('Multi Property Deal'!$B$19="","",'Multi Property Deal'!$B$19) | G41: =IF('Multi Property Deal'!$M$19="","",'Multi Property Deal'!$M$19) | H41: =IF('Multi Property Deal'!$P$19="","",'Multi Property Deal'!$P$19) | I41: =IF(B41="","",IF(SUM('Multi Property Deal'!$R$19:$R$21)=0,0,SUM('Multi Property Deal'!$R$19:$R$21)))
B42: =IF('Multi Property Deal'!$B$22="","",'Multi Property Deal'!$B$22) | G42: =IF('Multi Property Deal'!$M$22="","",'Multi Property Deal'!$M$22) | H42: =IF('Multi Property Deal'!$P$22="","",'Multi Property Deal'!$P$22) | I42: =IF(B42="","",IF(SUM('Multi Property Deal'!$R$22:$R$24)=0,0,SUM('Multi Property Deal'!$R$22:$R$24)))
B43: =IF('Multi Property Deal'!$B$25="","",'Multi Property Deal'!$B$25) | G43: =IF('Multi Property Deal'!$M$25="","",'Multi Property Deal'!$M$25) | H43: =IF('Multi Property Deal'!$P$25="","",'Multi Property Deal'!$P$25) | I43: =IF(B43="","",IF(SUM('Multi Property Deal'!$R$22:$R$24)=0,0,SUM('Multi Property Deal'!$R$22:$R$24)))
B44: =IF('Multi Property Deal'!$B$28="","",'Multi Property Deal'!$B$28) | G44: =IF('Multi Property Deal'!$M$28="","",'Multi Property Deal'!$M$28) | H44: =IF('Multi Property Deal'!$P$28="","",'Multi Property Deal'!$P$28) | I44: =IF(B44="","",IF(SUM('Multi Property Deal'!$R$28:$R$30)=0,0,SUM('Multi Property Deal'!$R$28:$R$30)))
B45: =IF('Multi Property Deal'!$B$31="","",'Multi Property Deal'!$B$31) | G45: =IF('Multi Property Deal'!$M$31="","",'Multi Property Deal'!$M$31) | H45: =IF('Multi Property Deal'!$P$31="","",'Multi Property Deal'!$P$31) | I45: =IF(B45="","",IF(SUM('Multi Property Deal'!$R$31:$R$33)=0,0,SUM('Multi Property Deal'!$R$31:$R$33)))
B46: =IF('Multi Property Deal'!$B$34="","",'Multi Property Deal'!$B$34) | G46: =IF('Multi Property Deal'!$M$34="","",'Multi Property Deal'!$M$34) | H46: =IF('Multi Property Deal'!$P$34="","",'Multi Property Deal'!$P$34) | I46: =IF(B46="","",IF(SUM('Multi Property Deal'!$R$34:$R$36)=0,0,SUM('Multi Property Deal'!$R$34:$R$36)))

Sheet DIP
A1: Automatic DIP production - choose Print to Microsft PDF for a email DIP
A2: THIS IS SET TEXT THAT WILL BE PRINTED - DO NOT AMEND COLUMNS A to D | F2: Shows rows to check | G2: Applicant Type | H2: ='Input Sheet'!C12 -> 0
F3: UW TO CHECK | G3: NOTES FOR THE UNDERWRITER | H3: Overwrite - new value? | I3: Notes for overwrite | J3: Formula pull through
A4: Decision in Principle | B4: =IF(H4="",J4,H4) -> 45989 | F4: ← Check | G4: Means variable value to the left to check or amend (amends to the right) | I4: Defaults to todays date | J4: =IF(H4="",TODAY(),H4) -> 45989
A5: Proposed Loan to: | B5: =IF(H2="Personal",IF(H5="",'Input Sheet'!C8,H5),(IF(H5="",'Input Sheet'!C8,H5)&" (Company No: "&J5&")")) -> xxxxx (Company No: XXXXXXXXX) | F5: ← Check | I5: Company Number | J5: XXXXXXXXX
